Workbook
Name budget: 'Budget Dashboard'!$L1
Name budget_range: 'Budget Dashboard'!$Q1
Name budget_rank: 'Budget Dashboard'!$R1
Name comb_rank: 'Budget Dashboard'!$S1
Name comb_rank_norm: 'Budget Dashboard'!$U1
Name comb_rank_norm_run_range: 'Budget Dashboard'!$V1
Name comb_rank_range: 'Budget Dashboard'!$T1
Name comb_rank_unique: 'Budget Dashboard'!$W1
Name current_date: DATE(2022,3,15)
Name expenses_header_row: ROW(Expenses[[#Headers],[Expenses]])
Name expenses_max_row: MAX(ROW(Expenses[]))
Name expenses_min_row: MIN(ROW(Expenses[]))
Name expenses_total_row: ROW('Budget Planning'!$C$46)
Name header_row_id: 'Budget Dashboard'!$D1
Name income_header_row: ROW(Income[[#Headers],[Income]])
Name income_max_row: MAX(ROW(Income[]))
Name income_min_row: MIN(ROW(Income[]))
Name income_total_row: ROW('Budget Planning'!$C$27)
Name is_cat: 'Budget Dashboard'!$F1
Name is_empty: 'Budget Dashboard'!$H1
Name is_header: 'Budget Dashboard'!$E1
Name is_total: 'Budget Dashboard'!$G1
Name item: 'Budget Dashboard'!$J1
Name out_budget: 'Budget Dashboard'!$AA1
Name out_percentage_completed: 'Budget Dashboard'!$AB1
Name out_tracked: 'Budget Dashboard'!$Z1
Name row_id: 'Budget Dashboard'!$C1
Name savings_header_row: ROW(Savings[[#Headers],[Savings]])
Name savings_max_row: MAX(ROW(Savings[]))
Name savings_min_row: MIN(ROW(Savings[]))
Name savings_top_row: ROW(Savings[[#Headers],[Savings]])
Name savings_total_row: ROW('Budget Planning'!$C$65)
Name selected_period: Calculations!$E$20
Name selected_period_display: Calculations!$E$21
Name selected_year: Calculations!$E$19
Name Shift_late_income_starting_date: Settings!$E$18
Name Shift_late_income_status: Settings!$E$16
Name sort_max_row: 'Budget Dashboard'!$N1
Name sort_min_row: 'Budget Dashboard'!$M1
Name Starting_Year: Settings!$E$8
Name tracked: 'Budget Dashboard'!$K1
Name tracked_range: 'Budget Dashboard'!$O1
Name tracked_rank: 'Budget Dashboard'!$P1
Name type: 'Budget Dashboard'!$I1

Sheet Settings
B2: Settings
B6: General
D8: Starting Year: | E8: 2022 | G8: Set the starting year (yyyy) once at the beginning and do not change it again
B12: Budget Tracking & Dashboard
D14: Late Monthly Income
D16: Shift late income: | E16: Active | G16: Activate this option to treat late income received on or after a certain day of the month as income for the next month. This is especially recommended in case you receive your monthly paycheck towards the en d of the month and prefer to consider this income as disposable income.
D18: Starting on day x in month: | E18: 20

Sheet Budget Planning
B2: Budget Planning
E6: =Starting_Year -> 2022 | S6: =E6+1 -> 2023 | AG6: =S6+1 -> 2024 | AU6: =AG6+1 -> 2025 | BI6: =AU6+1 -> 2026 | BW6: =BI6+1 -> 2027 | CK6: =BW6+1 -> 2028 | CY6: =CK6+1 -> 2029 | DM6: =CY6+1 -> 2030 | EA6: =DM6+1 -> 2031 | EO6: =EA6+1 -> 2032
E7: {=IF(E8=0,"Jan ✓","Jan")} -> Jan | F7: {=IF(F8=0,"Feb ✓","Feb")} -> Feb | G7: {=IF(G8=0,"Mar ✓","Mar")} -> Mar | H7: {=IF(H8=0,"Apr ✓","Apr")} -> Apr ✓ | I7: {=IF(I8=0,"May ✓","May")} -> May | J7: {=IF(J8=0,"Jun ✓","Jun")} -> Jun | K7: {=IF(K8=0,"Jul ✓","Jul")} -> Jul ✓ | L7: {=IF(L8=0,"Aug ✓","Aug")} -> Aug ✓ | M7: {=IF(M8=0,"Sep ✓","Sep")} -> Sep ✓ | N7: {=IF(N8=0,"Oct ✓","Oct")} -> Oct ✓ | O7: {=IF(O8=0,"Nov ✓","Nov")} -> Nov ✓ | P7: {=IF(P8=0,"Dec ✓","Dec'")} -> Dec ✓ | Q7: {=IF(Q8=0,"Total ✓","Total")} -> Total | S7: {=IF(S8=0,"Jan ✓","Jan")} -> Jan ✓ | T7: {=IF(T8=0,"Feb ✓","Feb")} -> Feb ✓ | U7: {=IF(U8=0,"Mar ✓","Mar")} -> Mar ✓ | V7: {=IF(V8=0,"Apr ✓","Apr")} -> Apr ✓ | W7: {=IF(W8=0,"May ✓","May")} -> May ✓ | X7: {=IF(X8=0,"Jun ✓","Jun")} -> Jun ✓ | Y7: {=IF(Y8=0,"Jul ✓","Jul")} -> Jul ✓ | Z7: {=IF(Z8=0,"Aug ✓","Aug")} -> Aug ✓ | AA7: {=IF(AA8=0,"Sep ✓","Sep")} -> Sep ✓ | AB7: {=IF(AB8=0,"Oct ✓","Oct")} -> Oct ✓ | AC7: {=IF(AC8=0,"Nov ✓","Nov")} -> Nov ✓ | AD7: {=IF(AD8=0,"Dec ✓","Dec'")} -> Dec ✓ | AE7: {=IF(AE8=0,"Total ✓","Total")} -> Total ✓ | AG7: {=IF(AG8=0,"Jan ✓","Jan")} -> Jan ✓ | AH7: {=IF(AH8=0,"Feb ✓","Feb")} -> Feb ✓ | AI7: {=IF(AI8=0,"Mar ✓","Mar")} -> Mar ✓ | AJ7: {=IF(AJ8=0,"Apr ✓","Apr")} -> Apr ✓ | AK7: {=IF(AK8=0,"May ✓","May")} -> May ✓ | AL7: {=IF(AL8=0,"Jun ✓","Jun")} -> Jun ✓ | AM7: {=IF(AM8=0,"Jul ✓","Jul")} -> Jul ✓ | AN7: {=IF(AN8=0,"Aug ✓","Aug")} -> Aug ✓ | AO7: {=IF(AO8=0,"Sep ✓","Sep")} -> Sep ✓ | AP7: {=IF(AP8=0,"Oct ✓","Oct")} -> Oct ✓ | AQ7: {=IF(AQ8=0,"Nov ✓","Nov")} -> Nov ✓ | AR7: {=IF(AR8=0,"Dec ✓","Dec'")} -> Dec ✓ | AS7: {=IF(AS8=0,"Total ✓","Total")} -> Total ✓ | AU7: {=IF(AU8=0,"Jan ✓","Jan")} -> Jan ✓ | AV7: {=IF(AV8=0,"Feb ✓","Feb")} -> Feb ✓ | AW7: {=IF(AW8=0,"Mar ✓","Mar")} -> Mar ✓ | AX7: {=IF(AX8=0,"Apr ✓","Apr")} -> Apr ✓ | AY7: {=IF(AY8=0,"May ✓","May")} -> May ✓ | AZ7: {=IF(AZ8=0,"Jun ✓","Jun")} -> Jun ✓ | BA7: {=IF(BA8=0,"Jul ✓","Jul")} -> Jul ✓ | BB7: {=IF(BB8=0,"Aug ✓","Aug")} -> Aug ✓ | BC7: {=IF(BC8=0,"Sep ✓","Sep")} -> Sep ✓ | BD7: {=IF(BD8=0,"Oct ✓","Oct")} -> Oct ✓ | BE7: {=IF(BE8=0,"Nov ✓","Nov")} -> Nov ✓ | BF7: {=IF(BF8=0,"Dec ✓","Dec'")} -> Dec ✓ | BG7: {=IF(BG8=0,"Total ✓","Total")} -> Total ✓ | BI7: {=IF(BI8=0,"Jan ✓","Jan")} -> Jan ✓ | BJ7: {=IF(BJ8=0,"Feb ✓","Feb")} -> Feb ✓ | BK7: {=IF(BK8=0,"Mar ✓","Mar")} -> Mar ✓ | BL7: {=IF(BL8=0,"Apr ✓","Apr")} -> Apr ✓ | BM7: {=IF(BM8=0,"May ✓","May")} -> May ✓ | BN7: {=IF(BN8=0,"Jun ✓","Jun")} -> Jun ✓ | BO7: {=IF(BO8=0,"Jul ✓","Jul")} -> Jul ✓ | BP7: {=IF(BP8=0,"Aug ✓","Aug")} -> Aug ✓ | BQ7: {=IF(BQ8=0,"Sep ✓","Sep")} -> Sep ✓ | BR7: {=IF(BR8=0,"Oct ✓","Oct")} -> Oct ✓ | BS7: {=IF(BS8=0,"Nov ✓","Nov")} -> Nov ✓ | BT7: {=IF(BT8=0,"Dec ✓","Dec'")} -> Dec ✓ | BU7: {=IF(BU8=0,"Total ✓","Total")} -> Total ✓ | BW7: {=IF(BW8=0,"Jan ✓","Jan")} -> Jan ✓ | BX7: {=IF(BX8=0,"Feb ✓","Feb")} -> Feb ✓ | BY7: {=IF(BY8=0,"Mar ✓","Mar")} -> Mar ✓ | BZ7: {=IF(BZ8=0,"Apr ✓","Apr")} -> Apr ✓ | CA7: {=IF(CA8=0,"May ✓","May")} -> May ✓ | CB7: {=IF(CB8=0,"Jun ✓","Jun")} -> Jun ✓ | CC7: {=IF(CC8=0,"Jul ✓","Jul")} -> Jul ✓ | CD7: {=IF(CD8=0,"Aug ✓","Aug")} -> Aug ✓ | CE7: {=IF(CE8=0,"Sep ✓","Sep")} -> Sep ✓ | CF7: {=IF(CF8=0,"Oct ✓","Oct")} -> Oct ✓ | CG7: {=IF(CG8=0,"Nov ✓","Nov")} -> Nov ✓ | CH7: {=IF(CH8=0,"Dec ✓","Dec'")} -> Dec ✓ | CI7: {=IF(CI8=0,"Total ✓","Total")} -> Total ✓ | CK7: {=IF(CK8=0,"Jan ✓","Jan")} -> Jan ✓ | CL7: {=IF(CL8=0,"Feb ✓","Feb")} -> Feb ✓ | CM7: {=IF(CM8=0,"Mar ✓","Mar")} -> Mar ✓ | CN7: {=IF(CN8=0,"Apr ✓","Apr")} -> Apr ✓ | CO7: {=IF(CO8=0,"May ✓","May")} -> May ✓ | CP7: {=IF(CP8=0,"Jun ✓","Jun")} -> Jun ✓ | CQ7: {=IF(CQ8=0,"Jul ✓","Jul")} -> Jul ✓ | CR7: {=IF(CR8=0,"Aug ✓","Aug")} -> Aug ✓ | CS7: {=IF(CS8=0,"Sep ✓","Sep")} -> Sep ✓ | CT7: {=IF(CT8=0,"Oct ✓","Oct")} -> Oct ✓ | CU7: {=IF(CU8=0,"Nov ✓","Nov")} -> Nov ✓ | CV7: {=IF(CV8=0,"Dec ✓","Dec'")} -> Dec ✓ | CW7: {=IF(CW8=0,"Total ✓","Total")} -> Total ✓ | CY7: {=IF(CY8=0,"Jan ✓","Jan")} -> Jan ✓ | CZ7: {=IF(CZ8=0,"Feb ✓","Feb")} -> Feb ✓ | DA7: {=IF(DA8=0,"Mar ✓","Mar")} -> Mar ✓ | DB7: {=IF(DB8=0,"Apr ✓","Apr")} -> Apr ✓ | DC7: {=IF(DC8=0,"May ✓","May")} -> May ✓ | DD7: {=IF(DD8=0,"Jun ✓","Jun")} -> Jun ✓ | DE7: {=IF(DE8=0,"Jul ✓","Jul")} -> Jul ✓ | DF7: {=IF(DF8=0,"Aug ✓","Aug")} -> Aug ✓ | DG7: {=IF(DG8=0,"Sep ✓","Sep")} -> Sep ✓ | DH7: {=IF(DH8=0,"Oct ✓","Oct")} -> Oct ✓ | DI7: {=IF(DI8=0,"Nov ✓","Nov")} -> Nov ✓ | DJ7: {=IF(DJ8=0,"Dec ✓","Dec'")} -> Dec ✓ | DK7: {=IF(DK8=0,"Total ✓","Total")} -> Total ✓ | DM7: {=IF(DM8=0,"Jan ✓","Jan")} -> Jan ✓ | DN7: {=IF(DN8=0,"Feb ✓","Feb")} -> Feb ✓ | DO7: {=IF(DO8=0,"Mar ✓","Mar")} -> Mar ✓ | DP7: {=IF(DP8=0,"Apr ✓","Apr")} -> Apr ✓ | DQ7: {=IF(DQ8=0,"May ✓","May")} -> May ✓ | DR7: {=IF(DR8=0,"Jun ✓","Jun")} -> Jun ✓ | DS7: {=IF(DS8=0,"Jul ✓","Jul")} -> Jul ✓ | DT7: {=IF(DT8=0,"Aug ✓","Aug")} -> Aug ✓ | DU7: {=IF(DU8=0,"Sep ✓","Sep")} -> Sep ✓ | DV7: {=IF(DV8=0,"Oct ✓","Oct")} -> Oct ✓ | DW7: {=IF(DW8=0,"Nov ✓","Nov")} -> Nov ✓ | DX7: {=IF(DX8=0,"Dec ✓","Dec'")} -> Dec ✓ | DY7: {=IF(DY8=0,"Total ✓","Total")} -> Total ✓ | EA7: {=IF(EA8=0,"Jan ✓","Jan")} -> Jan ✓ | EB7: {=IF(EB8=0,"Feb ✓","Feb")} -> Feb ✓ | EC7: {=IF(EC8=0,"Mar ✓","Mar")} -> Mar ✓ | ED7: {=IF(ED8=0,"Apr ✓","Apr")} -> Apr ✓ | EE7: {=IF(EE8=0,"May ✓","May")} -> May ✓ | EF7: {=IF(EF8=0,"Jun ✓","Jun")} -> Jun ✓ | EG7: {=IF(EG8=0,"Jul ✓","Jul")} -> Jul ✓ | EH7: {=IF(EH8=0,"Aug ✓","Aug")} -> Aug ✓ | EI7: {=IF(EI8=0,"Sep ✓","Sep")} -> Sep ✓ | EJ7: {=IF(EJ8=0,"Oct ✓","Oct")} -> Oct ✓ | EK7: {=IF(EK8=0,"Nov ✓","Nov")} -> Nov ✓ | EL7: {=IF(EL8=0,"Dec ✓","Dec'")} -> Dec ✓ | EM7: {=IF(EM8=0,"Total ✓","Total")} -> Total ✓ | EO7: {=IF(EO8=0,"Jan ✓","Jan")} -> Jan ✓ | EP7: {=IF(EP8=0,"Feb ✓","Feb")} -> Feb ✓ | EQ7: {=IF(EQ8=0,"Mar ✓","Mar")} -> Mar ✓ | ER7: {=IF(ER8=0,"Apr ✓","Apr")} -> Apr ✓ | ES7: {=IF(ES8=0,"May ✓","May")} -> May ✓ | ET7: {=IF(ET8=0,"Jun ✓","Jun")} -> Jun ✓ | EU7: {=IF(EU8=0,"Jul ✓","Jul")} -> Jul ✓ | EV7: {=IF(EV8=0,"Aug ✓","Aug")} -> Aug ✓ | EW7: {=IF(EW8=0,"Sep ✓","Sep")} -> Sep ✓ | EX7: {=IF(EX8=0,"Oct ✓","Oct")} -> Oct ✓ | EY7: {=IF(EY8=0,"Nov ✓","Nov")} -> Nov ✓ | EZ7: {=IF(EZ8=0,"Dec ✓","Dec'")} -> Dec ✓ | FA7: {=IF(FA8=0,"Total ✓","Total")} -> Total ✓
C8: To be allocated: | E8: =E27-(E46+E65) -> -6150 | F8: =F27-(F46+F65) -> 6511 | G8: =G27-(G46+G65) -> -5998 | H8: =H27-(H46+H65) -> 0 | I8: =I27-(I46+I65) -> -15531 | J8: =J27-(J46+J65) -> -513 | K8: =K27-(K46+K65) -> 0 | L8: =L27-(L46+L65) -> 0 | ... Q8: =Q27-(Q46+Q65) -> -21681 | S8: =S27-(S46+S65) -> 0 | T8: =T27-(T46+T65) -> 0 | U8: =U27-(U46+U65) -> 0 | V8: =V27-(V46+V65) -> 0 | W8: =W27-(W46+W65) -> 0 | X8: =X27-(X46+X65) -> 0 | Y8: =Y27-(Y46+Y65) -> 0 | Z8: =Z27-(Z46+Z65) -> 0 | ... AE8: =AE27-(AE46+AE65) -> 0 | AG8: =AG27-(AG46+AG65) -> 0 | AH8: =AH27-(AH46+AH65) -> 0 | AI8: =AI27-(AI46+AI65) -> 0 | AJ8: =AJ27-(AJ46+AJ65) -> 0 | AK8: =AK27-(AK46+AK65) -> 0 | AL8: =AL27-(AL46+AL65) -> 0 | AM8: =AM27-(AM46+AM65) -> 0 | AN8: =AN27-(AN46+AN65) -> 0 | ... AS8: =AS27-(AS46+AS65) -> 0 | AU8: =AU27-(AU46+AU65) -> 0 | AV8: =AV27-(AV46+AV65) -> 0 | AW8: =AW27-(AW46+AW65) -> 0 | AX8: =AX27-(AX46+AX65) -> 0 | AY8: =AY27-(AY46+AY65) -> 0 | AZ8: =AZ27-(AZ46+AZ65) -> 0 | BA8: =BA27-(BA46+BA65) -> 0 | BB8: =BB27-(BB46+BB65) -> 0 | ... BG8: =BG27-(BG46+BG65) -> 0 | BI8: =BI27-(BI46+BI65) -> 0 | BJ8: =BJ27-(BJ46+BJ65) -> 0 | BK8: =BK27-(BK46+BK65) -> 0 | BL8: =BL27-(BL46+BL65) -> 0 | BM8: =BM27-(BM46+BM65) -> 0 | BN8: =BN27-(BN46+BN65) -> 0 | BO8: =BO27-(BO46+BO65) -> 0 | BP8: =BP27-(BP46+BP65) -> 0 | ... BU8: =BU27-(BU46+BU65) -> 0 | BW8: =BW27-(BW46+BW65) -> 0 | BX8: =BX27-(BX46+BX65) -> 0 | BY8: =BY27-(BY46+BY65) -> 0 | BZ8: =BZ27-(BZ46+BZ65) -> 0 | CA8: =CA27-(CA46+CA65) -> 0 | CB8: =CB27-(CB46+CB65) -> 0 | CC8: =CC27-(CC46+CC65) -> 0 | CD8: =CD27-(CD46+CD65) -> 0 | ... CI8: =CI27-(CI46+CI65) -> 0 | CK8: =CK27-(CK46+CK65) -> 0 | CL8: =CL27-(CL46+CL65) -> 0 | CM8: =CM27-(CM46+CM65) -> 0 | CN8: =CN27-(CN46+CN65) -> 0 | CO8: =CO27-(CO46+CO65) -> 0 | CP8: =CP27-(CP46+CP65) -> 0 | CQ8: =CQ27-(CQ46+CQ65) -> 0 | CR8: =CR27-(CR46+CR65) -> 0 | ... CW8: =CW27-(CW46+CW65) -> 0 | CY8: =CY27-(CY46+CY65) -> 0 | CZ8: =CZ27-(CZ46+CZ65) -> 0 | DA8: =DA27-(DA46+DA65) -> 0 | DB8: =DB27-(DB46+DB65) -> 0 | DC8: =DC27-(DC46+DC65) -> 0 | DD8: =DD27-(DD46+DD65) -> 0 | DE8: =DE27-(DE46+DE65) -> 0 | DF8: =DF27-(DF46+DF65) -> 0 | ... DK8: =DK27-(DK46+DK65) -> 0 | DM8: =DM27-(DM46+DM65) -> 0 | DN8: =DN27-(DN46+DN65) -> 0 | DO8: =DO27-(DO46+DO65) -> 0 | DP8: =DP27-(DP46+DP65) -> 0 | DQ8: =DQ27-(DQ46+DQ65) -> 0 | DR8: =DR27-(DR46+DR65) -> 0 | DS8: =DS27-(DS46+DS65) -> 0 | DT8: =DT27-(DT46+DT65) -> 0 | ... DY8: =DY27-(DY46+DY65) -> 0 | EA8: =EA27-(EA46+EA65) -> 0 | EB8: =EB27-(EB46+EB65) -> 0 | EC8: =EC27-(EC46+EC65) -> 0 | ED8: =ED27-(ED46+ED65) -> 0 | EE8: =EE27-(EE46+EE65) -> 0 | EF8: =EF27-(EF46+EF65) -> 0 | EG8: =EG27-(EG46+EG65) -> 0 | EH8: =EH27-(EH46+EH65) -> 0 | ... EM8: =EM27-(EM46+EM65) -> 0 | EO8: =EO27-(EO46+EO65) -> 0 | EP8: =EP27-(EP46+EP65) -> 0 | EQ8: =EQ27-(EQ46+EQ65) -> 0 | ER8: =ER27-(ER46+ER65) -> 0 | ES8: =ES27-(ES46+ES65) -> 0 | ET8: =ET27-(ET46+ET65) -> 0 | EU8: =EU27-(EU46+EU65) -> 0 | EV8: =EV27-(EV46+EV65) -> 0 | ... FA8: =FA27-(FA46+FA65) -> 0
C10: Income | E10: {=DATE(E$6,1,1)} -> 44562 | F10: {=DATE(E$6,2,1)} -> 44593 | G10: {=DATE(E$6,3,1)} -> 44621 | H10: {=DATE(E$6,4,1)} -> 44652 | I10: {=DATE(E$6,5,1)} -> 44682 | J10: {=DATE(E$6,6,1)} -> 44713 | K10: {=DATE(E$6,7,1)} -> 44743 | L10: {=DATE(E$6,8,1)} -> 44774 | M10: {=DATE(E$6,9,1)} -> 44805 | N10: {=DATE(E$6,10,1)} -> 44835 | O10: {=DATE(E$6,11,1)} -> 44866 | P10: {=DATE(E$6,12,1)} -> 44896 | Q10: {=E$6} -> 2022 | S10: {=DATE(S$6,1,1)} -> 44927 | T10: {=DATE(S$6,2,1)} -> 44958 | U10: {=DATE(S$6,3,1)} -> 44986 | V10: {=DATE(S$6,4,1)} -> 45017 | W10: {=DATE(S$6,5,1)} -> 45047 | X10: {=DATE(S$6,6,1)} -> 45078 | Y10: {=DATE(S$6,7,1)} -> 45108 | Z10: {=DATE(S$6,8,1)} -> 45139 | AA10: {=DATE(S$6,9,1)} -> 45170 | AB10: {=DATE(S$6,10,1)} -> 45200 | AC10: {=DATE(S$6,11,1)} -> 45231 | AD10: {=DATE(S$6,12,1)} -> 45261 | AE10: {=S$6} -> 2023 | AG10: {=DATE(AG$6,1,1)} -> 45292 | AH10: {=DATE(AG$6,2,1)} -> 45323 | AI10: {=DATE(AG$6,3,1)} -> 45352 | AJ10: {=DATE(AG$6,4,1)} -> 45383 | AK10: {=DATE(AG$6,5,1)} -> 45413 | AL10: {=DATE(AG$6,6,1)} -> 45444 | AM10: {=DATE(AG$6,7,1)} -> 45474 | AN10: {=DATE(AG$6,8,1)} -> 45505 | AO10: {=DATE(AG$6,9,1)} -> 45536 | AP10: {=DATE(AG$6,10,1)} -> 45566 | AQ10: {=DATE(AG$6,11,1)} -> 45597 | AR10: {=DATE(AG$6,12,1)} -> 45627 | AS10: {=AG$6} -> 2024 | AU10: {=DATE(AU$6,1,1)} -> 45658 | AV10: {=DATE(AU$6,2,1)} -> 45689 | AW10: {=DATE(AU$6,3,1)} -> 45717 | AX10: {=DATE(AU$6,4,1)} -> 45748 | AY10: {=DATE(AU$6,5,1)} -> 45778 | AZ10: {=DATE(AU$6,6,1)} -> 45809 | BA10: {=DATE(AU$6,7,1)} -> 45839 | BB10: {=DATE(AU$6,8,1)} -> 45870 | BC10: {=DATE(AU$6,9,1)} -> 45901 | BD10: {=DATE(AU$6,10,1)} -> 45931 | BE10: {=DATE(AU$6,11,1)} -> 45962 | BF10: {=DATE(AU$6,12,1)} -> 45992 | BG10: {=AU$6} -> 2025 | BI10: {=DATE(BI$6,1,1)} -> 46023 | BJ10: {=DATE(BI$6,2,1)} -> 46054 | BK10: {=DATE(BI$6,3,1)} -> 46082 | BL10: {=DATE(BI$6,4,1)} -> 46113 | BM10: {=DATE(BI$6,5,1)} -> 46143 | BN10: {=DATE(BI$6,6,1)} -> 46174 | BO10: {=DATE(BI$6,7,1)} -> 46204 | BP10: {=DATE(BI$6,8,1)} -> 46235 | BQ10: {=DATE(BI$6,9,1)} -> 46266 | BR10: {=DATE(BI$6,10,1)} -> 46296 | BS10: {=DATE(BI$6,11,1)} -> 46327 | BT10: {=DATE(BI$6,12,1)} -> 46357 | BU10: {=BI$6} -> 2026 | BW10: {=DATE(BW$6,1,1)} -> 46388 | BX10: {=DATE(BW$6,2,1)} -> 46419 | BY10: {=DATE(BW$6,3,1)} -> 46447 | BZ10: {=DATE(BW$6,4,1)} -> 46478 | CA10: {=DATE(BW$6,5,1)} -> 46508 | CB10: {=DATE(BW$6,6,1)} -> 46539 | CC10: {=DATE(BW$6,7,1)} -> 46569 | CD10: {=DATE(BW$6,8,1)} -> 46600 | CE10: {=DATE(BW$6,9,1)} -> 46631 | CF10: {=DATE(BW$6,10,1)} -> 46661 | CG10: {=DATE(BW$6,11,1)} -> 46692 | CH10: {=DATE(BW$6,12,1)} -> 46722 | CI10: {=BW$6} -> 2027 | CK10: {=DATE(CK$6,1,1)} -> 46753 | CL10: {=DATE(CK$6,2,1)} -> 46784 | CM10: {=DATE(CK$6,3,1)} -> 46813 | CN10: {=DATE(CK$6,4,1)} -> 46844 | CO10: {=DATE(CK$6,5,1)} -> 46874 | CP10: {=DATE(CK$6,6,1)} -> 46905 | CQ10: {=DATE(CK$6,7,1)} -> 46935 | CR10: {=DATE(CK$6,8,1)} -> 46966 | CS10: {=DATE(CK$6,9,1)} -> 46997 | CT10: {=DATE(CK$6,10,1)} -> 47027 | CU10: {=DATE(CK$6,11,1)} -> 47058 | CV10: {=DATE(CK$6,12,1)} -> 47088 | CW10: {=CK$6} -> 2028 | CY10: {=DATE(CY$6,1,1)} -> 47119 | CZ10: {=DATE(CY$6,2,1)} -> 47150 | DA10: {=DATE(CY$6,3,1)} -> 47178 | DB10: {=DATE(CY$6,4,1)} -> 47209 | DC10: {=DATE(CY$6,5,1)} -> 47239 | DD10: {=DATE(CY$6,6,1)} -> 47270 | DE10: {=DATE(CY$6,7,1)} -> 47300 | DF10: {=DATE(CY$6,8,1)} -> 47331 | DG10: {=DATE(CY$6,9,1)} -> 47362 | DH10: {=DATE(CY$6,10,1)} -> 47392 | DI10: {=DATE(CY$6,11,1)} -> 47423 | DJ10: {=DATE(CY$6,12,1)} -> 47453 | DK10: {=CY$6} -> 2029 | DM10: {=DATE(DM$6,1,1)} -> 47484 | DN10: {=DATE(DM$6,2,1)} -> 47515 | DO10: {=DATE(DM$6,3,1)} -> 47543 | DP10: {=DATE(DM$6,4,1)} -> 47574 | DQ10: {=DATE(DM$6,5,1)} -> 47604 | DR10: {=DATE(DM$6,6,1)} -> 47635 | DS10: {=DATE(DM$6,7,1)} -> 47665 | DT10: {=DATE(DM$6,8,1)} -> 47696 | DU10: {=DATE(DM$6,9,1)} -> 47727 | DV10: {=DATE(DM$6,10,1)} -> 47757 | DW10: {=DATE(DM$6,11,1)} -> 47788 | DX10: {=DATE(DM$6,12,1)} -> 47818 | DY10: {=DM$6} -> 2030 | EA10: {=DATE(EA$6,1,1)} -> 47849 | EB10: {=DATE(EA$6,2,1)} -> 47880 | EC10: {=DATE(EA$6,3,1)} -> 47908 | ED10: {=DATE(EA$6,4,1)} -> 47939 | EE10: {=DATE(EA$6,5,1)} -> 47969 | EF10: {=DATE(EA$6,6,1)} -> 48000 | EG10: {=DATE(EA$6,7,1)} -> 48030 | EH10: {=DATE(EA$6,8,1)} -> 48061 | EI10: {=DATE(EA$6,9,1)} -> 48092 | EJ10: {=DATE(EA$6,10,1)} -> 48122 | EK10: {=DATE(EA$6,11,1)} -> 48153 | EL10: {=DATE(EA$6,12,1)} -> 48183 | EM10: {=EA$6} -> 2031 | EO10: {=DATE(EO$6,1,1)} -> 48214 | EP10: {=DATE(EO$6,2,1)} -> 48245 | EQ10: {=DATE(EO$6,3,1)} -> 48274 | ER10: {=DATE(EO$6,4,1)} -> 48305 | ES10: {=DATE(EO$6,5,1)} -> 48335 | ET10: {=DATE(EO$6,6,1)} -> 48366 | EU10: {=DATE(EO$6,7,1)} -> 48396 | EV10: {=DATE(EO$6,8,1)} -> 48427 | EW10: {=DATE(EO$6,9,1)} -> 48458 | EX10: {=DATE(EO$6,10,1)} -> 48488 | EY10: {=DATE(EO$6,11,1)} -> 48519 | EZ10: {=DATE(EO$6,12,1)} -> 48549 | FA10: {=EO$6} -> 2032
C11: Employment | E11: 350 | Q11: {=SUM(E11:P11)} -> 350 | AE11: {=SUM(S11:AD11)} -> 0 | AS11: {=SUM(AG11:AR11)} -> 0 | BG11: {=SUM(AU11:BF11)} -> 0 | BU11: {=SUM(BI11:BT11)} -> 0 | CI11: {=SUM(BW11:CH11)} -> 0 | CW11: {=SUM(CK11:CV11)} -> 0 | DK11: {=SUM(CY11:DJ11)} -> 0 | DY11: {=SUM(DM11:DX11)} -> 0 | EM11: {=SUM(EA11:EL11)} -> 0 | FA11: {=SUM(EO11:EZ11)} -> 0
C12: Side Hustle | F12: 6511 | Q12: {=SUM(E12:P12)} -> 6511 | AE12: {=SUM(S12:AD12)} -> 0 | AS12: {=SUM(AG12:AR12)} -> 0 | BG12: {=SUM(AU12:BF12)} -> 0 | BU12: {=SUM(BI12:BT12)} -> 0 | CI12: {=SUM(BW12:CH12)} -> 0 | CW12: {=SUM(CK12:CV12)} -> 0 | DK12: {=SUM(CY12:DJ12)} -> 0 | DY12: {=SUM(DM12:DX12)} -> 0 | EM12: {=SUM(EA12:EL12)} -> 0 | FA12: {=SUM(EO12:EZ12)} -> 0
C13: Interest | G13: 614 | Q13: {=SUM(E13:P13)} -> 614 | AE13: {=SUM(S13:AD13)} -> 0 | AS13: {=SUM(AG13:AR13)} -> 0 | BG13: {=SUM(AU13:BF13)} -> 0 | BU13: {=SUM(BI13:BT13)} -> 0 | CI13: {=SUM(BW13:CH13)} -> 0 | CW13: {=SUM(CK13:CV13)} -> 0 | DK13: {=SUM(CY13:DJ13)} -> 0 | DY13: {=SUM(DM13:DX13)} -> 0 | EM13: {=SUM(EA13:EL13)} -> 0 | FA13: {=SUM(EO13:EZ13)} -> 0
C14: Enter Income Category | Q14: {=SUM(E14:P14)} -> 0 | AE14: {=SUM(S14:AD14)} -> 0 | AS14: {=SUM(AG14:AR14)} -> 0 | BG14: {=SUM(AU14:BF14)} -> 0 | BU14: {=SUM(BI14:BT14)} -> 0 | CI14: {=SUM(BW14:CH14)} -> 0 | CW14: {=SUM(CK14:CV14)} -> 0 | DK14: {=SUM(CY14:DJ14)} -> 0 | DY14: {=SUM(DM14:DX14)} -> 0 | EM14: {=SUM(EA14:EL14)} -> 0 | FA14: {=SUM(EO14:EZ14)} -> 0
C15: Enter Income Category | Q15: {=SUM(E15:P15)} -> 0 | AE15: {=SUM(S15:AD15)} -> 0 | AS15: {=SUM(AG15:AR15)} -> 0 | BG15: {=SUM(AU15:BF15)} -> 0 | BU15: {=SUM(BI15:BT15)} -> 0 | CI15: {=SUM(BW15:CH15)} -> 0 | CW15: {=SUM(CK15:CV15)} -> 0 | DK15: {=SUM(CY15:DJ15)} -> 0 | DY15: {=SUM(DM15:DX15)} -> 0 | EM15: {=SUM(EA15:EL15)} -> 0 | FA15: {=SUM(EO15:EZ15)} -> 0
C16: Enter Income Category | Q16: {=SUM(E16:P16)} -> 0 | AE16: {=SUM(S16:AD16)} -> 0 | AS16: {=SUM(AG16:AR16)} -> 0 | BG16: {=SUM(AU16:BF16)} -> 0 | BU16: {=SUM(BI16:BT16)} -> 0 | CI16: {=SUM(BW16:CH16)} -> 0 | CW16: {=SUM(CK16:CV16)} -> 0 | DK16: {=SUM(CY16:DJ16)} -> 0 | DY16: {=SUM(DM16:DX16)} -> 0 | EM16: {=SUM(EA16:EL16)} -> 0 | FA16: {=SUM(EO16:EZ16)} -> 0
C17: Enter Income Category | Q17: {=SUM(E17:P17)} -> 0 | AE17: {=SUM(S17:AD17)} -> 0 | AS17: {=SUM(AG17:AR17)} -> 0 | BG17: {=SUM(AU17:BF17)} -> 0 | BU17: {=SUM(BI17:BT17)} -> 0 | CI17: {=SUM(BW17:CH17)} -> 0 | CW17: {=SUM(CK17:CV17)} -> 0 | DK17: {=SUM(CY17:DJ17)} -> 0 | DY17: {=SUM(DM17:DX17)} -> 0 | EM17: {=SUM(EA17:EL17)} -> 0 | FA17: {=SUM(EO17:EZ17)} -> 0
C18: Enter Income Category | Q18: {=SUM(E18:P18)} -> 0 | AE18: {=SUM(S18:AD18)} -> 0 | AS18: {=SUM(AG18:AR18)} -> 0 | BG18: {=SUM(AU18:BF18)} -> 0 | BU18: {=SUM(BI18:BT18)} -> 0 | CI18: {=SUM(BW18:CH18)} -> 0 | CW18: {=SUM(CK18:CV18)} -> 0 | DK18: {=SUM(CY18:DJ18)} -> 0 | DY18: {=SUM(DM18:DX18)} -> 0 | EM18: {=SUM(EA18:EL18)} -> 0 | FA18: {=SUM(EO18:EZ18)} -> 0
C19: Enter Income Category | Q19: {=SUM(E19:P19)} -> 0 | AE19: {=SUM(S19:AD19)} -> 0 | AS19: {=SUM(AG19:AR19)} -> 0 | BG19: {=SUM(AU19:BF19)} -> 0 | BU19: {=SUM(BI19:BT19)} -> 0 | CI19: {=SUM(BW19:CH19)} -> 0 | CW19: {=SUM(CK19:CV19)} -> 0 | DK19: {=SUM(CY19:DJ19)} -> 0 | DY19: {=SUM(DM19:DX19)} -> 0 | EM19: {=SUM(EA19:EL19)} -> 0 | FA19: {=SUM(EO19:EZ19)} -> 0
C20: Enter Income Category | Q20: {=SUM(E20:P20)} -> 0 | AE20: {=SUM(S20:AD20)} -> 0 | AS20: {=SUM(AG20:AR20)} -> 0 | BG20: {=SUM(AU20:BF20)} -> 0 | BU20: {=SUM(BI20:BT20)} -> 0 | CI20: {=SUM(BW20:CH20)} -> 0 | CW20: {=SUM(CK20:CV20)} -> 0 | DK20: {=SUM(CY20:DJ20)} -> 0 | DY20: {=SUM(DM20:DX20)} -> 0 | EM20: {=SUM(EA20:EL20)} -> 0 | FA20: {=SUM(EO20:EZ20)} -> 0
C21: Enter Income Category | Q21: {=SUM(E21:P21)} -> 0 | AE21: {=SUM(S21:AD21)} -> 0 | AS21: {=SUM(AG21:AR21)} -> 0 | BG21: {=SUM(AU21:BF21)} -> 0 | BU21: {=SUM(BI21:BT21)} -> 0 | CI21: {=SUM(BW21:CH21)} -> 0 | CW21: {=SUM(CK21:CV21)} -> 0 | DK21: {=SUM(CY21:DJ21)} -> 0 | DY21: {=SUM(DM21:DX21)} -> 0 | EM21: {=SUM(EA21:EL21)} -> 0 | FA21: {=SUM(EO21:EZ21)} -> 0
C22: Enter Income Category | Q22: {=SUM(E22:P22)} -> 0 | AE22: {=SUM(S22:AD22)} -> 0 | AS22: {=SUM(AG22:AR22)} -> 0 | BG22: {=SUM(AU22:BF22)} -> 0 | BU22: {=SUM(BI22:BT22)} -> 0 | CI22: {=SUM(BW22:CH22)} -> 0 | CW22: {=SUM(CK22:CV22)} -> 0 | DK22: {=SUM(CY22:DJ22)} -> 0 | DY22: {=SUM(DM22:DX22)} -> 0 | EM22: {=SUM(EA22:EL22)} -> 0 | FA22: {=SUM(EO22:EZ22)} -> 0
C23: Enter Income Category | Q23: {=SUM(E23:P23)} -> 0 | AE23: {=SUM(S23:AD23)} -> 0 | AS23: {=SUM(AG23:AR23)} -> 0 | BG23: {=SUM(AU23:BF23)} -> 0 | BU23: {=SUM(BI23:BT23)} -> 0 | CI23: {=SUM(BW23:CH23)} -> 0 | CW23: {=SUM(CK23:CV23)} -> 0 | DK23: {=SUM(CY23:DJ23)} -> 0 | DY23: {=SUM(DM23:DX23)} -> 0 | EM23: {=SUM(EA23:EL23)} -> 0 | FA23: {=SUM(EO23:EZ23)} -> 0
C24: Enter Income Category | Q24: {=SUM(E24:P24)} -> 0 | AE24: {=SUM(S24:AD24)} -> 0 | AS24: {=SUM(AG24:AR24)} -> 0 | BG24: {=SUM(AU24:BF24)} -> 0 | BU24: {=SUM(BI24:BT24)} -> 0 | CI24: {=SUM(BW24:CH24)} -> 0 | CW24: {=SUM(CK24:CV24)} -> 0 | DK24: {=SUM(CY24:DJ24)} -> 0 | DY24: {=SUM(DM24:DX24)} -> 0 | EM24: {=SUM(EA24:EL24)} -> 0 | FA24: {=SUM(EO24:EZ24)} -> 0
C25: Enter Income Category | Q25: {=SUM(E25:P25)} -> 0 | AE25: {=SUM(S25:AD25)} -> 0 | AS25: {=SUM(AG25:AR25)} -> 0 | BG25: {=SUM(AU25:BF25)} -> 0 | BU25: {=SUM(BI25:BT25)} -> 0 | CI25: {=SUM(BW25:CH25)} -> 0 | CW25: {=SUM(CK25:CV25)} -> 0 | DK25: {=SUM(CY25:DJ25)} -> 0 | DY25: {=SUM(DM25:DX25)} -> 0 | EM25: {=SUM(EA25:EL25)} -> 0 | FA25: {=SUM(EO25:EZ25)} -> 0
C26: Enter Income Category | Q26: {=SUM(E26:P26)} -> 0 | AE26: {=SUM(S26:AD26)} -> 0 | AS26: {=SUM(AG26:AR26)} -> 0 | BG26: {=SUM(AU26:BF26)} -> 0 | BU26: {=SUM(BI26:BT26)} -> 0 | CI26: {=SUM(BW26:CH26)} -> 0 | CW26: {=SUM(CK26:CV26)} -> 0 | DK26: {=SUM(CY26:DJ26)} -> 0 | DY26: {=SUM(DM26:DX26)} -> 0 | EM26: {=SUM(EA26:EL26)} -> 0 | FA26: {=SUM(EO26:EZ26)} -> 0
C27: Total | E27: {=SUM(INDIRECT(ADDRESS(income_min_row, COLUMN()) & ":" & ADDRESS(income_max_row, COLUMN())))} -> 350 | F27: {=SUM(INDIRECT(ADDRESS(income_min_row, COLUMN()) & ":" & ADDRESS(income_max_row, COLUMN())))} -> 6511 | G27: {=SUM(INDIRECT(ADDRESS(income_min_row, COLUMN()) & ":" & ADDRESS(income_max_row, COLUMN())))} -> 614 | H27: {=SUM(INDIRECT(ADDRESS(income_min_row, COLUMN()) & ":" & ADDRESS(income_max_row, COLUMN())))} -> 0 | I27: {=SUM(INDIRECT(ADDRESS(income_min_row, COLUMN()) & ":" & ADDRESS(income_max_row, COLUMN())))} -> 0 | J27: {=SUM(INDIRECT(ADDRESS(income_min_row, COLUMN()) & ":" & ADDRESS(income_max_row, COLUMN())))} -> 0 | K27: {=SUM(INDIRECT(ADDRESS(income_min_row, COLUMN()) & ":" & ADDRESS(income_max_row, COLUMN())))} -> 0 | L27: {=SUM(INDIRECT(ADDRESS(income_min_row, COLUMN()) & ":" & ADDRESS(income_max_row, COLUMN())))} -> 0 | ... Q27: {=SUM(INDIRECT(ADDRESS(income_min_row, COLUMN()) & ":" & ADDRESS(income_max_row, COLUMN())))} -> 7475 | S27: {=SUM(INDIRECT(ADDRESS(income_min_row, COLUMN()) & ":" & ADDRESS(income_max_row, COLUMN())))} -> 0 | T27: {=SUM(INDIRECT(ADDRESS(income_min_row, COLUMN()) & ":" & ADDRESS(income_max_row, COLUMN())))} -> 0 | U27: {=SUM(INDIRECT(ADDRESS(income_min_row, COLUMN()) & ":" & ADDRESS(income_max_row, COLUMN())))} -> 0 | V27: {=SUM(INDIRECT(ADDRESS(income_min_row, COLUMN()) & ":" & ADDRESS(income_max_row, COLUMN())))} -> 0 | W27: {=SUM(INDIRECT(ADDRESS(income_min_row, COLUMN()) & ":" & ADDRESS(income_max_row, COLUMN())))} -> 0 | X27: {=SUM(INDIRECT(ADDRESS(income_min_row, COLUMN()) & ":" & ADDRESS(income_max_row, COLUMN())))} -> 0 | Y27: {=SUM(INDIRECT(ADDRESS(income_min_row, COLUMN()) & ":" & ADDRESS(income_max_row, COLUMN())))} -> 0 | Z27: {=SUM(INDIRECT(ADDRESS(income_min_row, COLUMN()) & ":" & ADDRESS(income_max_row, COLUMN())))} -> 0 | ... AE27: {=SUM(INDIRECT(ADDRESS(income_min_row, COLUMN()) & ":" & ADDRESS(income_max_row, COLUMN())))} -> 0 | AG27: {=SUM(INDIRECT(ADDRESS(income_min_row, COLUMN()) & ":" & ADDRESS(income_max_row, COLUMN())))} -> 0 | AH27: {=SUM(INDIRECT(ADDRESS(income_min_row, COLUMN()) & ":" & ADDRESS(income_max_row, COLUMN())))} -> 0 | AI27: {=SUM(INDIRECT(ADDRESS(income_min_row, COLUMN()) & ":" & ADDRESS(income_max_row, COLUMN())))} -> 0 | AJ27: {=SUM(INDIRECT(ADDRESS(income_min_row, COLUMN()) & ":" & ADDRESS(income_max_row, COLUMN())))} -> 0 | AK27: {=SUM(INDIRECT(ADDRESS(income_min_row, COLUMN()) & ":" & ADDRESS(income_max_row, COLUMN())))} -> 0 | AL27: {=SUM(INDIRECT(ADDRESS(income_min_row, COLUMN()) & ":" & ADDRESS(income_max_row, COLUMN())))} -> 0 | AM27: {=SUM(INDIRECT(ADDRESS(income_min_row, COLUMN()) & ":" & ADDRESS(income_max_row, COLUMN())))} -> 0 | AN27: {=SUM(INDIRECT(ADDRESS(income_min_row, COLUMN()) & ":" & ADDRESS(income_max_row, COLUMN())))} -> 0 | ... AS27: {=SUM(INDIRECT(ADDRESS(income_min_row, COLUMN()) & ":" & ADDRESS(income_max_row, COLUMN())))} -> 0 | AU27: {=SUM(INDIRECT(ADDRESS(income_min_row, COLUMN()) & ":" & ADDRESS(income_max_row, COLUMN())))} -> 0 | AV27: {=SUM(INDIRECT(ADDRESS(income_min_row, COLUMN()) & ":" & ADDRESS(income_max_row, COLUMN())))} -> 0 | AW27: {=SUM(INDIRECT(ADDRESS(income_min_row, COLUMN()) & ":" & ADDRESS(income_max_row, COLUMN())))} -> 0 | AX27: {=SUM(INDIRECT(ADDRESS(income_min_row, COLUMN()) & ":" & ADDRESS(income_max_row, COLUMN())))} -> 0 | AY27: {=SUM(INDIRECT(ADDRESS(income_min_row, COLUMN()) & ":" & ADDRESS(income_max_row, COLUMN())))} -> 0 | AZ27: {=SUM(INDIRECT(ADDRESS(income_min_row, COLUMN()) & ":" & ADDRESS(income_max_row, COLUMN())))} -> 0 | BA27: {=SUM(INDIRECT(ADDRESS(income_min_row, COLUMN()) & ":" & ADDRESS(income_max_row, COLUMN())))} -> 0 | BB27: {=SUM(INDIRECT(ADDRESS(income_min_row, COLUMN()) & ":" & ADDRESS(income_max_row, COLUMN())))} -> 0 | ... BG27: {=SUM(INDIRECT(ADDRESS(income_min_row, COLUMN()) & ":" & ADDRESS(income_max_row, COLUMN())))} -> 0 | BI27: {=SUM(INDIRECT(ADDRESS(income_min_row, COLUMN()) & ":" & ADDRESS(income_max_row, COLUMN())))} -> 0 | BJ27: {=SUM(INDIRECT(ADDRESS(income_min_row, COLUMN()) & ":" & ADDRESS(income_max_row, COLUMN())))} -> 0 | BK27: {=SUM(INDIRECT(ADDRESS(income_min_row, COLUMN()) & ":" & ADDRESS(income_max_row, COLUMN())))} -> 0 | BL27: {=SUM(INDIRECT(ADDRESS(income_min_row, COLUMN()) & ":" & ADDRESS(income_max_row, COLUMN())))} -> 0 | BM27: {=SUM(INDIRECT(ADDRESS(income_min_row, COLUMN()) & ":" & ADDRESS(income_max_row, COLUMN())))} -> 0 | BN27: {=SUM(INDIRECT(ADDRESS(income_min_row, COLUMN()) & ":" & ADDRESS(income_max_row, COLUMN())))} -> 0 | BO27: {=SUM(INDIRECT(ADDRESS(income_min_row, COLUMN()) & ":" & ADDRESS(income_max_row, COLUMN())))} -> 0 | BP27: {=SUM(INDIRECT(ADDRESS(income_min_row, COLUMN()) & ":" & ADDRESS(income_max_row, COLUMN())))} -> 0 | ... BU27: {=SUM(INDIRECT(ADDRESS(income_min_row, COLUMN()) & ":" & ADDRESS(income_max_row, COLUMN())))} -> 0 | BW27: {=SUM(INDIRECT(ADDRESS(income_min_row, COLUMN()) & ":" & ADDRESS(income_max_row, COLUMN())))} -> 0 | BX27: {=SUM(INDIRECT(ADDRESS(income_min_row, COLUMN()) & ":" & ADDRESS(income_max_row, COLUMN())))} -> 0 | BY27: {=SUM(INDIRECT(ADDRESS(income_min_row, COLUMN()) & ":" & ADDRESS(income_max_row, COLUMN())))} -> 0 | BZ27: {=SUM(INDIRECT(ADDRESS(income_min_row, COLUMN()) & ":" & ADDRESS(income_max_row, COLUMN())))} -> 0 | CA27: {=SUM(INDIRECT(ADDRESS(income_min_row, COLUMN()) & ":" & ADDRESS(income_max_row, COLUMN())))} -> 0 | CB27: {=SUM(INDIRECT(ADDRESS(income_min_row, COLUMN()) & ":" & ADDRESS(income_max_row, COLUMN())))} -> 0 | CC27: {=SUM(INDIRECT(ADDRESS(income_min_row, COLUMN()) & ":" & ADDRESS(income_max_row, COLUMN())))} -> 0 | CD27: {=SUM(INDIRECT(ADDRESS(income_min_row, COLUMN()) & ":" & ADDRESS(income_max_row, COLUMN())))} -> 0 | ... CI27: {=SUM(INDIRECT(ADDRESS(income_min_row, COLUMN()) & ":" & ADDRESS(income_max_row, COLUMN())))} -> 0 | CK27: {=SUM(INDIRECT(ADDRESS(income_min_row, COLUMN()) & ":" & ADDRESS(income_max_row, COLUMN())))} -> 0 | CL27: {=SUM(INDIRECT(ADDRESS(income_min_row, COLUMN()) & ":" & ADDRESS(income_max_row, COLUMN())))} -> 0 | CM27: {=SUM(INDIRECT(ADDRESS(income_min_row, COLUMN()) & ":" & ADDRESS(income_max_row, COLUMN())))} -> 0 | CN27: {=SUM(INDIRECT(ADDRESS(income_min_row, COLUMN()) & ":" & ADDRESS(income_max_row, COLUMN())))} -> 0 | CO27: {=SUM(INDIRECT(ADDRESS(income_min_row, COLUMN()) & ":" & ADDRESS(income_max_row, COLUMN())))} -> 0 | CP27: {=SUM(INDIRECT(ADDRESS(income_min_row, COLUMN()) & ":" & ADDRESS(income_max_row, COLUMN())))} -> 0 | CQ27: {=SUM(INDIRECT(ADDRESS(income_min_row, COLUMN()) & ":" & ADDRESS(income_max_row, COLUMN())))} -> 0 | CR27: {=SUM(INDIRECT(ADDRESS(income_min_row, COLUMN()) & ":" & ADDRESS(income_max_row, COLUMN())))} -> 0 | ... CW27: {=SUM(INDIRECT(ADDRESS(income_min_row, COLUMN()) & ":" & ADDRESS(income_max_row, COLUMN())))} -> 0 | CY27: {=SUM(INDIRECT(ADDRESS(income_min_row, COLUMN()) & ":" & ADDRESS(income_max_row, COLUMN())))} -> 0 | CZ27: {=SUM(INDIRECT(ADDRESS(income_min_row, COLUMN()) & ":" & ADDRESS(income_max_row, COLUMN())))} -> 0 | DA27: {=SUM(INDIRECT(ADDRESS(income_min_row, COLUMN()) & ":" & ADDRESS(income_max_row, COLUMN())))} -> 0 | DB27: {=SUM(INDIRECT(ADDRESS(income_min_row, COLUMN()) & ":" & ADDRESS(income_max_row, COLUMN())))} -> 0 | DC27: {=SUM(INDIRECT(ADDRESS(income_min_row, COLUMN()) & ":" & ADDRESS(income_max_row, COLUMN())))} -> 0 | DD27: {=SUM(INDIRECT(ADDRESS(income_min_row, COLUMN()) & ":" & ADDRESS(income_max_row, COLUMN())))} -> 0 | DE27: {=SUM(INDIRECT(ADDRESS(income_min_row, COLUMN()) & ":" & ADDRESS(income_max_row, COLUMN())))} -> 0 | DF27: {=SUM(INDIRECT(ADDRESS(income_min_row, COLUMN()) & ":" & ADDRESS(income_max_row, COLUMN())))} -> 0 | ... DK27: {=SUM(INDIRECT(ADDRESS(income_min_row, COLUMN()) & ":" & ADDRESS(income_max_row, COLUMN())))} -> 0 | DM27: {=SUM(INDIRECT(ADDRESS(income_min_row, COLUMN()) & ":" & ADDRESS(income_max_row, COLUMN())))} -> 0 | DN27: {=SUM(INDIRECT(ADDRESS(income_min_row, COLUMN()) & ":" & ADDRESS(income_max_row, COLUMN())))} -> 0 | DO27: {=SUM(INDIRECT(ADDRESS(income_min_row, COLUMN()) & ":" & ADDRESS(income_max_row, COLUMN())))} -> 0 | DP27: {=SUM(INDIRECT(ADDRESS(income_min_row, COLUMN()) & ":" & ADDRESS(income_max_row, COLUMN())))} -> 0 | DQ27: {=SUM(INDIRECT(ADDRESS(income_min_row, COLUMN()) & ":" & ADDRESS(income_max_row, COLUMN())))} -> 0 | DR27: {=SUM(INDIRECT(ADDRESS(income_min_row, COLUMN()) & ":" & ADDRESS(income_max_row, COLUMN())))} -> 0 | DS27: {=SUM(INDIRECT(ADDRESS(income_min_row, COLUMN()) & ":" & ADDRESS(income_max_row, COLUMN())))} -> 0 | DT27: {=SUM(INDIRECT(ADDRESS(income_min_row, COLUMN()) & ":" & ADDRESS(income_max_row, COLUMN())))} -> 0 | ... DY27: {=SUM(INDIRECT(ADDRESS(income_min_row, COLUMN()) & ":" & ADDRESS(income_max_row, COLUMN())))} -> 0 | EA27: {=SUM(INDIRECT(ADDRESS(income_min_row, COLUMN()) & ":" & ADDRESS(income_max_row, COLUMN())))} -> 0 | EB27: {=SUM(INDIRECT(ADDRESS(income_min_row, COLUMN()) & ":" & ADDRESS(income_max_row, COLUMN())))} -> 0 | EC27: {=SUM(INDIRECT(ADDRESS(income_min_row, COLUMN()) & ":" & ADDRESS(income_max_row, COLUMN())))} -> 0 | ED27: {=SUM(INDIRECT(ADDRESS(income_min_row, COLUMN()) & ":" & ADDRESS(income_max_row, COLUMN())))} -> 0 | EE27: {=SUM(INDIRECT(ADDRESS(income_min_row, COLUMN()) & ":" & ADDRESS(income_max_row, COLUMN())))} -> 0 | EF27: {=SUM(INDIRECT(ADDRESS(income_min_row, COLUMN()) & ":" & ADDRESS(income_max_row, COLUMN())))} -> 0 | EG27: {=SUM(INDIRECT(ADDRESS(income_min_row, COLUMN()) & ":" & ADDRESS(income_max_row, COLUMN())))} -> 0 | EH27: {=SUM(INDIRECT(ADDRESS(income_min_row, COLUMN()) & ":" & ADDRESS(income_max_row, COLUMN())))} -> 0 | ... EM27: {=SUM(INDIRECT(ADDRESS(income_min_row, COLUMN()) & ":" & ADDRESS(income_max_row, COLUMN())))} -> 0 | EO27: {=SUM(INDIRECT(ADDRESS(income_min_row, COLUMN()) & ":" & ADDRESS(income_max_row, COLUMN())))} -> 0 | EP27: {=SUM(INDIRECT(ADDRESS(income_min_row, COLUMN()) & ":" & ADDRESS(income_max_row, COLUMN())))} -> 0 | EQ27: {=SUM(INDIRECT(ADDRESS(income_min_row, COLUMN()) & ":" & ADDRESS(income_max_row, COLUMN())))} -> 0 | ER27: {=SUM(INDIRECT(ADDRESS(income_min_row, COLUMN()) & ":" & ADDRESS(income_max_row, COLUMN())))} -> 0 | ES27: {=SUM(INDIRECT(ADDRESS(income_min_row, COLUMN()) & ":" & ADDRESS(income_max_row, COLUMN())))} -> 0 | ET27: {=SUM(INDIRECT(ADDRESS(income_min_row, COLUMN()) & ":" & ADDRESS(income_max_row, COLUMN())))} -> 0 | EU27: {=SUM(INDIRECT(ADDRESS(income_min_row, COLUMN()) & ":" & ADDRESS(income_max_row, COLUMN())))} -> 0 | EV27: {=SUM(INDIRECT(ADDRESS(income_min_row, COLUMN()) & ":" & ADDRESS(income_max_row, COLUMN())))} -> 0 | ... FA27: {=SUM(INDIRECT(ADDRESS(income_min_row, COLUMN()) & ":" & ADDRESS(income_max_row, COLUMN())))} -> 0
C29: Expenses | E29: {=DATE(E$6,1,1)} -> 44562 | F29: {=DATE(E$6,2,1)} -> 44593 | G29: {=DATE(E$6,3,1)} -> 44621 | H29: {=DATE(E$6,4,1)} -> 44652 | I29: {=DATE(E$6,5,1)} -> 44682 | J29: {=DATE(E$6,6,1)} -> 44713 | K29: {=DATE(E$6,7,1)} -> 44743 | L29: {=DATE(E$6,8,1)} -> 44774 | M29: {=DATE(E$6,9,1)} -> 44805 | N29: {=DATE(E$6,10,1)} -> 44835 | O29: {=DATE(E$6,11,1)} -> 44866 | P29: {=DATE(E$6,12,1)} -> 44896 | Q29: {=E$6} -> 2022 | S29: {=DATE(S$6,1,1)} -> 44927 | T29: {=DATE(S$6,2,1)} -> 44958 | U29: {=DATE(S$6,3,1)} -> 44986 | V29: {=DATE(S$6,4,1)} -> 45017 | W29: {=DATE(S$6,5,1)} -> 45047 | X29: {=DATE(S$6,6,1)} -> 45078 | Y29: {=DATE(S$6,7,1)} -> 45108 | Z29: {=DATE(S$6,8,1)} -> 45139 | AA29: {=DATE(S$6,9,1)} -> 45170 | AB29: {=DATE(S$6,10,1)} -> 45200 | AC29: {=DATE(S$6,11,1)} -> 45231 | AD29: {=DATE(S$6,12,1)} -> 45261 | AE29: {=S$6} -> 2023 | AG29: {=DATE(AG$6,1,1)} -> 45292 | AH29: {=DATE(AG$6,2,1)} -> 45323 | AI29: {=DATE(AG$6,3,1)} -> 45352 | AJ29: {=DATE(AG$6,4,1)} -> 45383 | AK29: {=DATE(AG$6,5,1)} -> 45413 | AL29: {=DATE(AG$6,6,1)} -> 45444 | AM29: {=DATE(AG$6,7,1)} -> 45474 | AN29: {=DATE(AG$6,8,1)} -> 45505 | AO29: {=DATE(AG$6,9,1)} -> 45536 | AP29: {=DATE(AG$6,10,1)} -> 45566 | AQ29: {=DATE(AG$6,11,1)} -> 45597 | AR29: {=DATE(AG$6,12,1)} -> 45627 | AS29: {=AG$6} -> 2024 | AU29: {=DATE(AU$6,1,1)} -> 45658 | AV29: {=DATE(AU$6,2,1)} -> 45689 | AW29: {=DATE(AU$6,3,1)} -> 45717 | AX29: {=DATE(AU$6,4,1)} -> 45748 | AY29: {=DATE(AU$6,5,1)} -> 45778 | AZ29: {=DATE(AU$6,6,1)} -> 45809 | BA29: {=DATE(AU$6,7,1)} -> 45839 | BB29: {=DATE(AU$6,8,1)} -> 45870 | BC29: {=DATE(AU$6,9,1)} -> 45901 | BD29: {=DATE(AU$6,10,1)} -> 45931 | BE29: {=DATE(AU$6,11,1)} -> 45962 | BF29: {=DATE(AU$6,12,1)} -> 45992 | BG29: {=AU$6} -> 2025 | BI29: {=DATE(BI$6,1,1)} -> 46023 | BJ29: {=DATE(BI$6,2,1)} -> 46054 | BK29: {=DATE(BI$6,3,1)} -> 46082 | BL29: {=DATE(BI$6,4,1)} -> 46113 | BM29: {=DATE(BI$6,5,1)} -> 46143 | BN29: {=DATE(BI$6,6,1)} -> 46174 | BO29: {=DATE(BI$6,7,1)} -> 46204 | BP29: {=DATE(BI$6,8,1)} -> 46235 | BQ29: {=DATE(BI$6,9,1)} -> 46266 | BR29: {=DATE(BI$6,10,1)} -> 46296 | BS29: {=DATE(BI$6,11,1)} -> 46327 | BT29: {=DATE(BI$6,12,1)} -> 46357 | BU29: {=BI$6} -> 2026 | BW29: {=DATE(BW$6,1,1)} -> 46388 | BX29: {=DATE(BW$6,2,1)} -> 46419 | BY29: {=DATE(BW$6,3,1)} -> 46447 | BZ29: {=DATE(BW$6,4,1)} -> 46478 | CA29: {=DATE(BW$6,5,1)} -> 46508 | CB29: {=DATE(BW$6,6,1)} -> 46539 | CC29: {=DATE(BW$6,7,1)} -> 46569 | CD29: {=DATE(BW$6,8,1)} -> 46600 | CE29: {=DATE(BW$6,9,1)} -> 46631 | CF29: {=DATE(BW$6,10,1)} -> 46661 | CG29: {=DATE(BW$6,11,1)} -> 46692 | CH29: {=DATE(BW$6,12,1)} -> 46722 | CI29: {=BW$6} -> 2027 | CK29: {=DATE(CK$6,1,1)} -> 46753 | CL29: {=DATE(CK$6,2,1)} -> 46784 | CM29: {=DATE(CK$6,3,1)} -> 46813 | CN29: {=DATE(CK$6,4,1)} -> 46844 | CO29: {=DATE(CK$6,5,1)} -> 46874 | CP29: {=DATE(CK$6,6,1)} -> 46905 | CQ29: {=DATE(CK$6,7,1)} -> 46935 | CR29: {=DATE(CK$6,8,1)} -> 46966 | CS29: {=DATE(CK$6,9,1)} -> 46997 | CT29: {=DATE(CK$6,10,1)} -> 47027 | CU29: {=DATE(CK$6,11,1)} -> 47058 | CV29: {=DATE(CK$6,12,1)} -> 47088 | CW29: {=CK$6} -> 2028 | CY29: {=DATE(CY$6,1,1)} -> 47119 | CZ29: {=DATE(CY$6,2,1)} -> 47150 | DA29: {=DATE(CY$6,3,1)} -> 47178 | DB29: {=DATE(CY$6,4,1)} -> 47209 | DC29: {=DATE(CY$6,5,1)} -> 47239 | DD29: {=DATE(CY$6,6,1)} -> 47270 | DE29: {=DATE(CY$6,7,1)} -> 47300 | DF29: {=DATE(CY$6,8,1)} -> 47331 | DG29: {=DATE(CY$6,9,1)} -> 47362 | DH29: {=DATE(CY$6,10,1)} -> 47392 | DI29: {=DATE(CY$6,11,1)} -> 47423 | DJ29: {=DATE(CY$6,12,1)} -> 47453 | DK29: {=CY$6} -> 2029 | DM29: {=DATE(DM$6,1,1)} -> 47484 | DN29: {=DATE(DM$6,2,1)} -> 47515 | DO29: {=DATE(DM$6,3,1)} -> 47543 | DP29: {=DATE(DM$6,4,1)} -> 47574 | DQ29: {=DATE(DM$6,5,1)} -> 47604 | DR29: {=DATE(DM$6,6,1)} -> 47635 | DS29: {=DATE(DM$6,7,1)} -> 47665 | DT29: {=DATE(DM$6,8,1)} -> 47696 | DU29: {=DATE(DM$6,9,1)} -> 47727 | DV29: {=DATE(DM$6,10,1)} -> 47757 | DW29: {=DATE(DM$6,11,1)} -> 47788 | DX29: {=DATE(DM$6,12,1)} -> 47818 | DY29: {=DM$6} -> 2030 | EA29: {=DATE(EA$6,1,1)} -> 47849 | EB29: {=DATE(EA$6,2,1)} -> 47880 | EC29: {=DATE(EA$6,3,1)} -> 47908 | ED29: {=DATE(EA$6,4,1)} -> 47939 | EE29: {=DATE(EA$6,5,1)} -> 47969 | EF29: {=DATE(EA$6,6,1)} -> 48000 | EG29: {=DATE(EA$6,7,1)} -> 48030 | EH29: {=DATE(EA$6,8,1)} -> 48061 | EI29: {=DATE(EA$6,9,1)} -> 48092 | EJ29: {=DATE(EA$6,10,1)} -> 48122 | EK29: {=DATE(EA$6,11,1)} -> 48153 | EL29: {=DATE(EA$6,12,1)} -> 48183 | EM29: {=EA$6} -> 2031 | EO29: {=DATE(EO$6,1,1)} -> 48214 | EP29: {=DATE(EO$6,2,1)} -> 48245 | EQ29: {=DATE(EO$6,3,1)} -> 48274 | ER29: {=DATE(EO$6,4,1)} -> 48305 | ES29: {=DATE(EO$6,5,1)} -> 48335 | ET29: {=DATE(EO$6,6,1)} -> 48366 | EU29: {=DATE(EO$6,7,1)} -> 48396 | EV29: {=DATE(EO$6,8,1)} -> 48427 | EW29: {=DATE(EO$6,9,1)} -> 48458 | EX29: {=DATE(EO$6,10,1)} -> 48488 | EY29: {=DATE(EO$6,11,1)} -> 48519 | EZ29: {=DATE(EO$6,12,1)} -> 48549 | FA29: {=EO$6} -> 2032
C30: Rent | E30: 6500 | Q30: {=SUM(E30:P30)} -> 6500 | AE30: {=SUM(S30:AD30)} -> 0 | AS30: {=SUM(AG30:AR30)} -> 0 | BG30: {=SUM(AU30:BF30)} -> 0 | BU30: {=SUM(BI30:BT30)} -> 0 | CI30: {=SUM(BW30:CH30)} -> 0 | CW30: {=SUM(CK30:CV30)} -> 0 | DK30: {=SUM(CY30:DJ30)} -> 0 | DY30: {=SUM(DM30:DX30)} -> 0 | EM30: {=SUM(EA30:EL30)} -> 0 | FA30: {=SUM(EO30:EZ30)} -> 0
C31: Groceries | G31: 6612 | Q31: {=SUM(E31:P31)} -> 6612 | AE31: {=SUM(S31:AD31)} -> 0 | AS31: {=SUM(AG31:AR31)} -> 0 | BG31: {=SUM(AU31:BF31)} -> 0 | BU31: {=SUM(BI31:BT31)} -> 0 | CI31: {=SUM(BW31:CH31)} -> 0 | CW31: {=SUM(CK31:CV31)} -> 0 | DK31: {=SUM(CY31:DJ31)} -> 0 | DY31: {=SUM(DM31:DX31)} -> 0 | EM31: {=SUM(EA31:EL31)} -> 0 | FA31: {=SUM(EO31:EZ31)} -> 0
C32: Transport | I32: 15531 | Q32: {=SUM(E32:P32)} -> 15531 | AE32: {=SUM(S32:AD32)} -> 0 | AS32: {=SUM(AG32:AR32)} -> 0 | BG32: {=SUM(AU32:BF32)} -> 0 | BU32: {=SUM(BI32:BT32)} -> 0 | CI32: {=SUM(BW32:CH32)} -> 0 | CW32: {=SUM(CK32:CV32)} -> 0 | DK32: {=SUM(CY32:DJ32)} -> 0 | DY32: {=SUM(DM32:DX32)} -> 0 | EM32: {=SUM(EA32:EL32)} -> 0 | FA32: {=SUM(EO32:EZ32)} -> 0
C33: Utilities | J33: 513 | Q33: {=SUM(E33:P33)} -> 513 | AE33: {=SUM(S33:AD33)} -> 0 | AS33: {=SUM(AG33:AR33)} -> 0 | BG33: {=SUM(AU33:BF33)} -> 0 | BU33: {=SUM(BI33:BT33)} -> 0 | CI33: {=SUM(BW33:CH33)} -> 0 | CW33: {=SUM(CK33:CV33)} -> 0 | DK33: {=SUM(CY33:DJ33)} -> 0 | DY33: {=SUM(DM33:DX33)} -> 0 | EM33: {=SUM(EA33:EL33)} -> 0 | FA33: {=SUM(EO33:EZ33)} -> 0
C34: Insurance | Q34: {=SUM(E34:P34)} -> 0 | AE34: {=SUM(S34:AD34)} -> 0 | AS34: {=SUM(AG34:AR34)} -> 0 | BG34: {=SUM(AU34:BF34)} -> 0 | BU34: {=SUM(BI34:BT34)} -> 0 | CI34: {=SUM(BW34:CH34)} -> 0 | CW34: {=SUM(CK34:CV34)} -> 0 | DK34: {=SUM(CY34:DJ34)} -> 0 | DY34: {=SUM(DM34:DX34)} -> 0 | EM34: {=SUM(EA34:EL34)} -> 0 | FA34: {=SUM(EO34:EZ34)} -> 0
C35: Clothing | Q35: {=SUM(E35:P35)} -> 0 | AE35: {=SUM(S35:AD35)} -> 0 | AS35: {=SUM(AG35:AR35)} -> 0 | BG35: {=SUM(AU35:BF35)} -> 0 | BU35: {=SUM(BI35:BT35)} -> 0 | CI35: {=SUM(BW35:CH35)} -> 0 | CW35: {=SUM(CK35:CV35)} -> 0 | DK35: {=SUM(CY35:DJ35)} -> 0 | DY35: {=SUM(DM35:DX35)} -> 0 | EM35: {=SUM(EA35:EL35)} -> 0 | FA35: {=SUM(EO35:EZ35)} -> 0
C36: Cosmetics | Q36: {=SUM(E36:P36)} -> 0 | AE36: {=SUM(S36:AD36)} -> 0 | AS36: {=SUM(AG36:AR36)} -> 0 | BG36: {=SUM(AU36:BF36)} -> 0 | BU36: {=SUM(BI36:BT36)} -> 0 | CI36: {=SUM(BW36:CH36)} -> 0 | CW36: {=SUM(CK36:CV36)} -> 0 | DK36: {=SUM(CY36:DJ36)} -> 0 | DY36: {=SUM(DM36:DX36)} -> 0 | EM36: {=SUM(EA36:EL36)} -> 0 | FA36: {=SUM(EO36:EZ36)} -> 0
C37: Medicine | Q37: {=SUM(E37:P37)} -> 0 | AE37: {=SUM(S37:AD37)} -> 0 | AS37: {=SUM(AG37:AR37)} -> 0 | BG37: {=SUM(AU37:BF37)} -> 0 | BU37: {=SUM(BI37:BT37)} -> 0 | CI37: {=SUM(BW37:CH37)} -> 0 | CW37: {=SUM(CK37:CV37)} -> 0 | DK37: {=SUM(CY37:DJ37)} -> 0 | DY37: {=SUM(DM37:DX37)} -> 0 | EM37: {=SUM(EA37:EL37)} -> 0 | FA37: {=SUM(EO37:EZ37)} -> 0
C38: Media | Q38: {=SUM(E38:P38)} -> 0 | AE38: {=SUM(S38:AD38)} -> 0 | AS38: {=SUM(AG38:AR38)} -> 0 | BG38: {=SUM(AU38:BF38)} -> 0 | BU38: {=SUM(BI38:BT38)} -> 0 | CI38: {=SUM(BW38:CH38)} -> 0 | CW38: {=SUM(CK38:CV38)} -> 0 | DK38: {=SUM(CY38:DJ38)} -> 0 | DY38: {=SUM(DM38:DX38)} -> 0 | EM38: {=SUM(EA38:EL38)} -> 0 | FA38: {=SUM(EO38:EZ38)} -> 0
C39: Fun & Vacation | Q39: {=SUM(E39:P39)} -> 0 | AE39: {=SUM(S39:AD39)} -> 0 | AS39: {=SUM(AG39:AR39)} -> 0 | BG39: {=SUM(AU39:BF39)} -> 0 | BU39: {=SUM(BI39:BT39)} -> 0 | CI39: {=SUM(BW39:CH39)} -> 0 | CW39: {=SUM(CK39:CV39)} -> 0 | DK39: {=SUM(CY39:DJ39)} -> 0 | DY39: {=SUM(DM39:DX39)} -> 0 | EM39: {=SUM(EA39:EL39)} -> 0 | FA39: {=SUM(EO39:EZ39)} -> 0
C40: Gifting | Q40: {=SUM(E40:P40)} -> 0 | AE40: {=SUM(S40:AD40)} -> 0 | AS40: {=SUM(AG40:AR40)} -> 0 | BG40: {=SUM(AU40:BF40)} -> 0 | BU40: {=SUM(BI40:BT40)} -> 0 | CI40: {=SUM(BW40:CH40)} -> 0 | CW40: {=SUM(CK40:CV40)} -> 0 | DK40: {=SUM(CY40:DJ40)} -> 0 | DY40: {=SUM(DM40:DX40)} -> 0 | EM40: {=SUM(EA40:EL40)} -> 0 | FA40: {=SUM(EO40:EZ40)} -> 0
C41: Miscellaneous | Q41: {=SUM(E41:P41)} -> 0 | AE41: {=SUM(S41:AD41)} -> 0 | AS41: {=SUM(AG41:AR41)} -> 0 | BG41: {=SUM(AU41:BF41)} -> 0 | BU41: {=SUM(BI41:BT41)} -> 0 | CI41: {=SUM(BW41:CH41)} -> 0 | CW41: {=SUM(CK41:CV41)} -> 0 | DK41: {=SUM(CY41:DJ41)} -> 0 | DY41: {=SUM(DM41:DX41)} -> 0 | EM41: {=SUM(EA41:EL41)} -> 0 | FA41: {=SUM(EO41:EZ41)} -> 0
C42: Enter Income Category | Q42: {=SUM(E42:P42)} -> 0 | AE42: {=SUM(S42:AD42)} -> 0 | AS42: {=SUM(AG42:AR42)} -> 0 | BG42: {=SUM(AU42:BF42)} -> 0 | BU42: {=SUM(BI42:BT42)} -> 0 | CI42: {=SUM(BW42:CH42)} -> 0 | CW42: {=SUM(CK42:CV42)} -> 0 | DK42: {=SUM(CY42:DJ42)} -> 0 | DY42: {=SUM(DM42:DX42)} -> 0 | EM42: {=SUM(EA42:EL42)} -> 0 | FA42: {=SUM(EO42:EZ42)} -> 0
C43: Enter Income Category | Q43: {=SUM(E43:P43)} -> 0 | AE43: {=SUM(S43:AD43)} -> 0 | AS43: {=SUM(AG43:AR43)} -> 0 | BG43: {=SUM(AU43:BF43)} -> 0 | BU43: {=SUM(BI43:BT43)} -> 0 | CI43: {=SUM(BW43:CH43)} -> 0 | CW43: {=SUM(CK43:CV43)} -> 0 | DK43: {=SUM(CY43:DJ43)} -> 0 | DY43: {=SUM(DM43:DX43)} -> 0 | EM43: {=SUM(EA43:EL43)} -> 0 | FA43: {=SUM(EO43:EZ43)} -> 0
C44: Enter Income Category | Q44: {=SUM(E44:P44)} -> 0 | AE44: {=SUM(S44:AD44)} -> 0 | AS44: {=SUM(AG44:AR44)} -> 0 | BG44: {=SUM(AU44:BF44)} -> 0 | BU44: {=SUM(BI44:BT44)} -> 0 | CI44: {=SUM(BW44:CH44)} -> 0 | CW44: {=SUM(CK44:CV44)} -> 0 | DK44: {=SUM(CY44:DJ44)} -> 0 | DY44: {=SUM(DM44:DX44)} -> 0 | EM44: {=SUM(EA44:EL44)} -> 0 | FA44: {=SUM(EO44:EZ44)} -> 0
C45: Enter Income Category | Q45: {=SUM(E45:P45)} -> 0 | AE45: {=SUM(S45:AD45)} -> 0 | AS45: {=SUM(AG45:AR45)} -> 0 | BG45: {=SUM(AU45:BF45)} -> 0 | BU45: {=SUM(BI45:BT45)} -> 0 | CI45: {=SUM(BW45:CH45)} -> 0 | CW45: {=SUM(CK45:CV45)} -> 0 | DK45: {=SUM(CY45:DJ45)} -> 0 | DY45: {=SUM(DM45:DX45)} -> 0 | EM45: {=SUM(EA45:EL45)} -> 0 | FA45: {=SUM(EO45:EZ45)} -> 0
C46: Total | E46: {=SUM(INDIRECT(ADDRESS(expenses_min_row, COLUMN()) & ":" & ADDRESS(expenses_max_row, COLUMN())))} -> 6500 | F46: {=SUM(INDIRECT(ADDRESS(expenses_min_row, COLUMN()) & ":" & ADDRESS(expenses_max_row, COLUMN())))} -> 0 | G46: {=SUM(INDIRECT(ADDRESS(expenses_min_row, COLUMN()) & ":" & ADDRESS(expenses_max_row, COLUMN())))} -> 6612 | H46: {=SUM(INDIRECT(ADDRESS(expenses_min_row, COLUMN()) & ":" & ADDRESS(expenses_max_row, COLUMN())))} -> 0 | I46: {=SUM(INDIRECT(ADDRESS(expenses_min_row, COLUMN()) & ":" & ADDRESS(expenses_max_row, COLUMN())))} -> 15531 | J46: {=SUM(INDIRECT(ADDRESS(expenses_min_row, COLUMN()) & ":" & ADDRESS(expenses_max_row, COLUMN())))} -> 513 | K46: {=SUM(INDIRECT(ADDRESS(expenses_min_row, COLUMN()) & ":" & ADDRESS(expenses_max_row, COLUMN())))} -> 0 | L46: {=SUM(INDIRECT(ADDRESS(expenses_min_row, COLUMN()) & ":" & ADDRESS(expenses_max_row, COLUMN())))} -> 0 | ... Q46: {=SUM(INDIRECT(ADDRESS(expenses_min_row, COLUMN()) & ":" & ADDRESS(expenses_max_row, COLUMN())))} -> 29156 | S46: {=SUM(INDIRECT(ADDRESS(expenses_min_row, COLUMN()) & ":" & ADDRESS(expenses_max_row, COLUMN())))} -> 0 | T46: {=SUM(INDIRECT(ADDRESS(expenses_min_row, COLUMN()) & ":" & ADDRESS(expenses_max_row, COLUMN())))} -> 0 | U46: {=SUM(INDIRECT(ADDRESS(expenses_min_row, COLUMN()) & ":" & ADDRESS(expenses_max_row, COLUMN())))} -> 0 | V46: {=SUM(INDIRECT(ADDRESS(expenses_min_row, COLUMN()) & ":" & ADDRESS(expenses_max_row, COLUMN())))} -> 0 | W46: {=SUM(INDIRECT(ADDRESS(expenses_min_row, COLUMN()) & ":" & ADDRESS(expenses_max_row, COLUMN())))} -> 0 | X46: {=SUM(INDIRECT(ADDRESS(expenses_min_row, COLUMN()) & ":" & ADDRESS(expenses_max_row, COLUMN())))} -> 0 | Y46: {=SUM(INDIRECT(ADDRESS(expenses_min_row, COLUMN()) & ":" & ADDRESS(expenses_max_row, COLUMN())))} -> 0 | Z46: {=SUM(INDIRECT(ADDRESS(expenses_min_row, COLUMN()) & ":" & ADDRESS(expenses_max_row, COLUMN())))} -> 0 | ... AE46: {=SUM(INDIRECT(ADDRESS(expenses_min_row, COLUMN()) & ":" & ADDRESS(expenses_max_row, COLUMN())))} -> 0 | AG46: {=SUM(INDIRECT(ADDRESS(expenses_min_row, COLUMN()) & ":" & ADDRESS(expenses_max_row, COLUMN())))} -> 0 | AH46: {=SUM(INDIRECT(ADDRESS(expenses_min_row, COLUMN()) & ":" & ADDRESS(expenses_max_row, COLUMN())))} -> 0 | AI46: {=SUM(INDIRECT(ADDRESS(expenses_min_row, COLUMN()) & ":" & ADDRESS(expenses_max_row, COLUMN())))} -> 0 | AJ46: {=SUM(INDIRECT(ADDRESS(expenses_min_row, COLUMN()) & ":" & ADDRESS(expenses_max_row, COLUMN())))} -> 0 | AK46: {=SUM(INDIRECT(ADDRESS(expenses_min_row, COLUMN()) & ":" & ADDRESS(expenses_max_row, COLUMN())))} -> 0 | AL46: {=SUM(INDIRECT(ADDRESS(expenses_min_row, COLUMN()) & ":" & ADDRESS(expenses_max_row, COLUMN())))} -> 0 | AM46: {=SUM(INDIRECT(ADDRESS(expenses_min_row, COLUMN()) & ":" & ADDRESS(expenses_max_row, COLUMN())))} -> 0 | AN46: {=SUM(INDIRECT(ADDRESS(expenses_min_row, COLUMN()) & ":" & ADDRESS(expenses_max_row, COLUMN())))} -> 0 | ... AS46: {=SUM(INDIRECT(ADDRESS(expenses_min_row, COLUMN()) & ":" & ADDRESS(expenses_max_row, COLUMN())))} -> 0 | AU46: {=SUM(INDIRECT(ADDRESS(expenses_min_row, COLUMN()) & ":" & ADDRESS(expenses_max_row, COLUMN())))} -> 0 | AV46: {=SUM(INDIRECT(ADDRESS(expenses_min_row, COLUMN()) & ":" & ADDRESS(expenses_max_row, COLUMN())))} -> 0 | AW46: {=SUM(INDIRECT(ADDRESS(expenses_min_row, COLUMN()) & ":" & ADDRESS(expenses_max_row, COLUMN())))} -> 0 | AX46: {=SUM(INDIRECT(ADDRESS(expenses_min_row, COLUMN()) & ":" & ADDRESS(expenses_max_row, COLUMN())))} -> 0 | AY46: {=SUM(INDIRECT(ADDRESS(expenses_min_row, COLUMN()) & ":" & ADDRESS(expenses_max_row, COLUMN())))} -> 0 | AZ46: {=SUM(INDIRECT(ADDRESS(expenses_min_row, COLUMN()) & ":" & ADDRESS(expenses_max_row, COLUMN())))} -> 0 | BA46: {=SUM(INDIRECT(ADDRESS(expenses_min_row, COLUMN()) & ":" & ADDRESS(expenses_max_row, COLUMN())))} -> 0 | BB46: {=SUM(INDIRECT(ADDRESS(expenses_min_row, COLUMN()) & ":" & ADDRESS(expenses_max_row, COLUMN())))} -> 0 | ... BG46: {=SUM(INDIRECT(ADDRESS(expenses_min_row, COLUMN()) & ":" & ADDRESS(expenses_max_row, COLUMN())))} -> 0 | BI46: {=SUM(INDIRECT(ADDRESS(expenses_min_row, COLUMN()) & ":" & ADDRESS(expenses_max_row, COLUMN())))} -> 0 | BJ46: {=SUM(INDIRECT(ADDRESS(expenses_min_row, COLUMN()) & ":" & ADDRESS(expenses_max_row, COLUMN())))} -> 0 | BK46: {=SUM(INDIRECT(ADDRESS(expenses_min_row, COLUMN()) & ":" & ADDRESS(expenses_max_row, COLUMN())))} -> 0 | BL46: {=SUM(INDIRECT(ADDRESS(expenses_min_row, COLUMN()) & ":" & ADDRESS(expenses_max_row, COLUMN())))} -> 0 | BM46: {=SUM(INDIRECT(ADDRESS(expenses_min_row, COLUMN()) & ":" & ADDRESS(expenses_max_row, COLUMN())))} -> 0 | BN46: {=SUM(INDIRECT(ADDRESS(expenses_min_row, COLUMN()) & ":" & ADDRESS(expenses_max_row, COLUMN())))} -> 0 | BO46: {=SUM(INDIRECT(ADDRESS(expenses_min_row, COLUMN()) & ":" & ADDRESS(expenses_max_row, COLUMN())))} -> 0 | BP46: {=SUM(INDIRECT(ADDRESS(expenses_min_row, COLUMN()) & ":" & ADDRESS(expenses_max_row, COLUMN())))} -> 0 | ... BU46: {=SUM(INDIRECT(ADDRESS(expenses_min_row, COLUMN()) & ":" & ADDRESS(expenses_max_row, COLUMN())))} -> 0 | BW46: {=SUM(INDIRECT(ADDRESS(expenses_min_row, COLUMN()) & ":" & ADDRESS(expenses_max_row, COLUMN())))} -> 0 | BX46: {=SUM(INDIRECT(ADDRESS(expenses_min_row, COLUMN()) & ":" & ADDRESS(expenses_max_row, COLUMN())))} -> 0 | BY46: {=SUM(INDIRECT(ADDRESS(expenses_min_row, COLUMN()) & ":" & ADDRESS(expenses_max_row, COLUMN())))} -> 0 | BZ46: {=SUM(INDIRECT(ADDRESS(expenses_min_row, COLUMN()) & ":" & ADDRESS(expenses_max_row, COLUMN())))} -> 0 | CA46: {=SUM(INDIRECT(ADDRESS(expenses_min_row, COLUMN()) & ":" & ADDRESS(expenses_max_row, COLUMN())))} -> 0 | CB46: {=SUM(INDIRECT(ADDRESS(expenses_min_row, COLUMN()) & ":" & ADDRESS(expenses_max_row, COLUMN())))} -> 0 | CC46: {=SUM(INDIRECT(ADDRESS(expenses_min_row, COLUMN()) & ":" & ADDRESS(expenses_max_row, COLUMN())))} -> 0 | CD46: {=SUM(INDIRECT(ADDRESS(expenses_min_row, COLUMN()) & ":" & ADDRESS(expenses_max_row, COLUMN())))} -> 0 | ... CI46: {=SUM(INDIRECT(ADDRESS(expenses_min_row, COLUMN()) & ":" & ADDRESS(expenses_max_row, COLUMN())))} -> 0 | CK46: {=SUM(INDIRECT(ADDRESS(expenses_min_row, COLUMN()) & ":" & ADDRESS(expenses_max_row, COLUMN())))} -> 0 | CL46: {=SUM(INDIRECT(ADDRESS(expenses_min_row, COLUMN()) & ":" & ADDRESS(expenses_max_row, COLUMN())))} -> 0 | CM46: {=SUM(INDIRECT(ADDRESS(expenses_min_row, COLUMN()) & ":" & ADDRESS(expenses_max_row, COLUMN())))} -> 0 | CN46: {=SUM(INDIRECT(ADDRESS(expenses_min_row, COLUMN()) & ":" & ADDRESS(expenses_max_row, COLUMN())))} -> 0 | CO46: {=SUM(INDIRECT(ADDRESS(expenses_min_row, COLUMN()) & ":" & ADDRESS(expenses_max_row, COLUMN())))} -> 0 | CP46: {=SUM(INDIRECT(ADDRESS(expenses_min_row, COLUMN()) & ":" & ADDRESS(expenses_max_row, COLUMN())))} -> 0 | CQ46: {=SUM(INDIRECT(ADDRESS(expenses_min_row, COLUMN()) & ":" & ADDRESS(expenses_max_row, COLUMN())))} -> 0 | CR46: {=SUM(INDIRECT(ADDRESS(expenses_min_row, COLUMN()) & ":" & ADDRESS(expenses_max_row, COLUMN())))} -> 0 | ... CW46: {=SUM(INDIRECT(ADDRESS(expenses_min_row, COLUMN()) & ":" & ADDRESS(expenses_max_row, COLUMN())))} -> 0 | CY46: {=SUM(INDIRECT(ADDRESS(expenses_min_row, COLUMN()) & ":" & ADDRESS(expenses_max_row, COLUMN())))} -> 0 | CZ46: {=SUM(INDIRECT(ADDRESS(expenses_min_row, COLUMN()) & ":" & ADDRESS(expenses_max_row, COLUMN())))} -> 0 | DA46: {=SUM(INDIRECT(ADDRESS(expenses_min_row, COLUMN()) & ":" & ADDRESS(expenses_max_row, COLUMN())))} -> 0 | DB46: {=SUM(INDIRECT(ADDRESS(expenses_min_row, COLUMN()) & ":" & ADDRESS(expenses_max_row, COLUMN())))} -> 0 | DC46: {=SUM(INDIRECT(ADDRESS(expenses_min_row, COLUMN()) & ":" & ADDRESS(expenses_max_row, COLUMN())))} -> 0 | DD46: {=SUM(INDIRECT(ADDRESS(expenses_min_row, COLUMN()) & ":" & ADDRESS(expenses_max_row, COLUMN())))} -> 0 | DE46: {=SUM(INDIRECT(ADDRESS(expenses_min_row, COLUMN()) & ":" & ADDRESS(expenses_max_row, COLUMN())))} -> 0 | DF46: {=SUM(INDIRECT(ADDRESS(expenses_min_row, COLUMN()) & ":" & ADDRESS(expenses_max_row, COLUMN())))} -> 0 | ... DK46: {=SUM(INDIRECT(ADDRESS(expenses_min_row, COLUMN()) & ":" & ADDRESS(expenses_max_row, COLUMN())))} -> 0 | DM46: {=SUM(INDIRECT(ADDRESS(expenses_min_row, COLUMN()) & ":" & ADDRESS(expenses_max_row, COLUMN())))} -> 0 | DN46: {=SUM(INDIRECT(ADDRESS(expenses_min_row, COLUMN()) & ":" & ADDRESS(expenses_max_row, COLUMN())))} -> 0 | DO46: {=SUM(INDIRECT(ADDRESS(expenses_min_row, COLUMN()) & ":" & ADDRESS(expenses_max_row, COLUMN())))} -> 0 | DP46: {=SUM(INDIRECT(ADDRESS(expenses_min_row, COLUMN()) & ":" & ADDRESS(expenses_max_row, COLUMN())))} -> 0 | DQ46: {=SUM(INDIRECT(ADDRESS(expenses_min_row, COLUMN()) & ":" & ADDRESS(expenses_max_row, COLUMN())))} -> 0 | DR46: {=SUM(INDIRECT(ADDRESS(expenses_min_row, COLUMN()) & ":" & ADDRESS(expenses_max_row, COLUMN())))} -> 0 | DS46: {=SUM(INDIRECT(ADDRESS(expenses_min_row, COLUMN()) & ":" & ADDRESS(expenses_max_row, COLUMN())))} -> 0 | DT46: {=SUM(INDIRECT(ADDRESS(expenses_min_row, COLUMN()) & ":" & ADDRESS(expenses_max_row, COLUMN())))} -> 0 | ... DY46: {=SUM(INDIRECT(ADDRESS(expenses_min_row, COLUMN()) & ":" & ADDRESS(expenses_max_row, COLUMN())))} -> 0 | EA46: {=SUM(INDIRECT(ADDRESS(expenses_min_row, COLUMN()) & ":" & ADDRESS(expenses_max_row, COLUMN())))} -> 0 | EB46: {=SUM(INDIRECT(ADDRESS(expenses_min_row, COLUMN()) & ":" & ADDRESS(expenses_max_row, COLUMN())))} -> 0 | EC46: {=SUM(INDIRECT(ADDRESS(expenses_min_row, COLUMN()) & ":" & ADDRESS(expenses_max_row, COLUMN())))} -> 0 | ED46: {=SUM(INDIRECT(ADDRESS(expenses_min_row, COLUMN()) & ":" & ADDRESS(expenses_max_row, COLUMN())))} -> 0 | EE46: {=SUM(INDIRECT(ADDRESS(expenses_min_row, COLUMN()) & ":" & ADDRESS(expenses_max_row, COLUMN())))} -> 0 | EF46: {=SUM(INDIRECT(ADDRESS(expenses_min_row, COLUMN()) & ":" & ADDRESS(expenses_max_row, COLUMN())))} -> 0 | EG46: {=SUM(INDIRECT(ADDRESS(expenses_min_row, COLUMN()) & ":" & ADDRESS(expenses_max_row, COLUMN())))} -> 0 | EH46: {=SUM(INDIRECT(ADDRESS(expenses_min_row, COLUMN()) & ":" & ADDRESS(expenses_max_row, COLUMN())))} -> 0 | ... EM46: {=SUM(INDIRECT(ADDRESS(expenses_min_row, COLUMN()) & ":" & ADDRESS(expenses_max_row, COLUMN())))} -> 0 | EO46: {=SUM(INDIRECT(ADDRESS(expenses_min_row, COLUMN()) & ":" & ADDRESS(expenses_max_row, COLUMN())))} -> 0 | EP46: {=SUM(INDIRECT(ADDRESS(expenses_min_row, COLUMN()) & ":" & ADDRESS(expenses_max_row, COLUMN())))} -> 0 | EQ46: {=SUM(INDIRECT(ADDRESS(expenses_min_row, COLUMN()) & ":" & ADDRESS(expenses_max_row, COLUMN())))} -> 0 | ER46: {=SUM(INDIRECT(ADDRESS(expenses_min_row, COLUMN()) & ":" & ADDRESS(expenses_max_row, COLUMN())))} -> 0 | ES46: {=SUM(INDIRECT(ADDRESS(expenses_min_row, COLUMN()) & ":" & ADDRESS(expenses_max_row, COLUMN())))} -> 0 | ET46: {=SUM(INDIRECT(ADDRESS(expenses_min_row, COLUMN()) & ":" & ADDRESS(expenses_max_row, COLUMN())))} -> 0 | EU46: {=SUM(INDIRECT(ADDRESS(expenses_min_row, COLUMN()) & ":" & ADDRESS(expenses_max_row, COLUMN())))} -> 0 | EV46: {=SUM(INDIRECT(ADDRESS(expenses_min_row, COLUMN()) & ":" & ADDRESS(expenses_max_row, COLUMN())))} -> 0 | ... FA46: {=SUM(INDIRECT(ADDRESS(expenses_min_row, COLUMN()) & ":" & ADDRESS(expenses_max_row, COLUMN())))} -> 0
...

Sheet Budget Tracking
B2: Budget Tracking
C11: Date | D11: Type | E11: Category | F11: Amount | G11: Details | H11: Balance | I11: Effective Date
C12: 44555 | D12: Income | E12: Employment | F12: 3500 | H12: {=SUMPRODUCT(Tracking[Amount], --(Tracking[Date]<=Tracking[[#This Row],[Date]]), (Tracking[Type]<>"Income") * (-1) + (Tracking[Type]="Income"))} -> 3500 | I12: =IF( AND(Tracking[[#This Row],[Type]]="Income", Shift_late_income_status="Active", DAY(Tracking[[#This Row],[Date]])>=Shift_late_income_starting_date), DATE(YEAR(Tracking[[#This Row],[Date]]), MONTH(Tracking[[#This Row],[Date]])+1, 1), Tracking[[#This Row],[Date]] ) -> 44562
C13: 44563 | D13: Expenses | E13: Rent | F13: 1200 | H13: {=SUMPRODUCT(Tracking[Amount], --(Tracking[Date]<=Tracking[[#This Row],[Date]]), (Tracking[Type]<>"Income") * (-1) + (Tracking[Type]="Income"))} -> 2300 | I13: =IF( AND(Tracking[[#This Row],[Type]]="Income", Shift_late_income_status="Active", DAY(Tracking[[#This Row],[Date]])>=Shift_late_income_starting_date), DATE(YEAR(Tracking[[#This Row],[Date]]), MONTH(Tracking[[#This Row],[Date]])+1, 1), Tracking[[#This Row],[Date]] ) -> 44563
C14: 44564 | D14: Expenses | E14: Clothing | F14: 150 | H14: {=SUMPRODUCT(Tracking[Amount], --(Tracking[Date]<=Tracking[[#This Row],[Date]]), (Tracking[Type]<>"Income") * (-1) + (Tracking[Type]="Income"))} -> 2150 | I14: =IF( AND(Tracking[[#This Row],[Type]]="Income", Shift_late_income_status="Active", DAY(Tracking[[#This Row],[Date]])>=Shift_late_income_starting_date), DATE(YEAR(Tracking[[#This Row],[Date]]), MONTH(Tracking[[#This Row],[Date]])+1, 1), Tracking[[#This Row],[Date]] ) -> 44564
C15: 44565 | D15: Savings | E15: Emergency Fund | F15: 1000 | H15: {=SUMPRODUCT(Tracking[Amount], --(Tracking[Date]<=Tracking[[#This Row],[Date]]), (Tracking[Type]<>"Income") * (-1) + (Tracking[Type]="Income"))} -> 1150 | I15: =IF( AND(Tracking[[#This Row],[Type]]="Income", Shift_late_income_status="Active", DAY(Tracking[[#This Row],[Date]])>=Shift_late_income_starting_date), DATE(YEAR(Tracking[[#This Row],[Date]]), MONTH(Tracking[[#This Row],[Date]])+1, 1), Tracking[[#This Row],[Date]] ) -> 44565
C16: 44597 | D16: Income | E16: Side Hustle | F16: 500 | H16: {=SUMPRODUCT(Tracking[Amount], --(Tracking[Date]<=Tracking[[#This Row],[Date]]), (Tracking[Type]<>"Income") * (-1) + (Tracking[Type]="Income"))} -> 1650 | I16: =IF( AND(Tracking[[#This Row],[Type]]="Income", Shift_late_income_status="Active", DAY(Tracking[[#This Row],[Date]])>=Shift_late_income_starting_date), DATE(YEAR(Tracking[[#This Row],[Date]]), MONTH(Tracking[[#This Row],[Date]])+1, 1), Tracking[[#This Row],[Date]] ) -> 44597
C17: 44599 | D17: Expenses | E17: Groceries | F17: 200 | H17: {=SUMPRODUCT(Tracking[Amount], --(Tracking[Date]<=Tracking[[#This Row],[Date]]), (Tracking[Type]<>"Income") * (-1) + (Tracking[Type]="Income"))} -> 1450 | I17: =IF( AND(Tracking[[#This Row],[Type]]="Income", Shift_late_income_status="Active", DAY(Tracking[[#This Row],[Date]])>=Shift_late_income_starting_date), DATE(YEAR(Tracking[[#This Row],[Date]]), MONTH(Tracking[[#This Row],[Date]])+1, 1), Tracking[[#This Row],[Date]] ) -> 44599
C18: 44600 | D18: Expenses | E18: Transport | F18: 100 | H18: {=SUMPRODUCT(Tracking[Amount], --(Tracking[Date]<=Tracking[[#This Row],[Date]]), (Tracking[Type]<>"Income") * (-1) + (Tracking[Type]="Income"))} -> 1350 | I18: =IF( AND(Tracking[[#This Row],[Type]]="Income", Shift_late_income_status="Active", DAY(Tracking[[#This Row],[Date]])>=Shift_late_income_starting_date), DATE(YEAR(Tracking[[#This Row],[Date]]), MONTH(Tracking[[#This Row],[Date]])+1, 1), Tracking[[#This Row],[Date]] ) -> 44600
C19: 44601 | D19: Savings | E19: Sinking Fund Future Payment | F19: 500 | H19: {=SUMPRODUCT(Tracking[Amount], --(Tracking[Date]<=Tracking[[#This Row],[Date]]), (Tracking[Type]<>"Income") * (-1) + (Tracking[Type]="Income"))} -> 850 | I19: =IF( AND(Tracking[[#This Row],[Type]]="Income", Shift_late_income_status="Active", DAY(Tracking[[#This Row],[Date]])>=Shift_late_income_starting_date), DATE(YEAR(Tracking[[#This Row],[Date]]), MONTH(Tracking[[#This Row],[Date]])+1, 1), Tracking[[#This Row],[Date]] ) -> 44601

Sheet Budget Dashboard
B2: Budget Dashboard
AQ5: Year
AN6: Select the year to view -> | AQ6: Current Year
AQ8: Period
AN9: Select the period to view -> | AQ9: Total Year
Y11: ="Breakdown - " & IF(selected_period="Total Year", selected_year & " (Total Year)", selected_period_display & " " & selected_year) -> Breakdown - 2022 (Total Year) | AF11: ="Summary - " & IF(selected_period="Total Year", selected_year & " (Total Year)", selected_period_display & " " & selected_year) -> Summary - 2022 (Total Year)
