Workbook
Name budget: 'Budget Dashboard'!$L1
Name budget_range: 'Budget Dashboard'!$Q1
Name budget_rank: 'Budget Dashboard'!$R1
Name cc_budget: Calculations!$K1
Name cc_delta: Calculations!$L1
Name cc_in_Focus: Calculations!$G1
Name cc_month_number: Calculations!$F1
Name cc_show_remaining_rudget: Calculations!$I1
Name cc_show_type: Calculations!$H1
Name cc_tracked: Calculations!$J1
Name cc_type: Calculations!$E1
Name comb_rank: 'Budget Dashboard'!$S1
Name comb_rank_norm: 'Budget Dashboard'!$U1
Name comb_rank_norm_run_range: 'Budget Dashboard'!$V1
Name comb_rank_range: 'Budget Dashboard'!$T1
Name comb_rank_unique: 'Budget Dashboard'!$W1
Name current_date: TODAY()
Name expenses_header_row: ROW(Expenses[[#Headers],[Expenses]])
Name expenses_max_row: MAX(ROW(Expenses[]))
Name expenses_min_row: MIN(ROW(Expenses[]))
Name expenses_total_row: ROW('Budget Planning'!$C$46)
Name header_row_id: 'Budget Dashboard'!$D1
Name income_header_row: ROW(Income[[#Headers],[Income]])
Name income_max_row: MAX(ROW(Income[]))
Name income_min_row: MIN(ROW(Income[]))
Name income_total_row: ROW('Budget Planning'!$C$27)
Name is_cat: 'Budget Dashboard'!$F1
Name is_empty: 'Budget Dashboard'!$H1
Name is_header: 'Budget Dashboard'!$E1
Name is_total: 'Budget Dashboard'!$G1
Name item: 'Budget Dashboard'!$J1
Name out_budget: 'Budget Dashboard'!$AA1
Name out_percentage_completed: 'Budget Dashboard'!$AB1
Name out_tracked: 'Budget Dashboard'!$Z1
Name row_id: 'Budget Dashboard'!$C1
Name savings_header_row: ROW(Savings[[#Headers],[Savings]])
Name savings_max_row: MAX(ROW(Savings[]))
Name savings_min_row: MIN(ROW(Savings[]))
Name Savings_rate_calculation_type: Settings!$E$22
Name savings_top_row: ROW(Savings[[#Headers],[Savings]])
Name savings_total_row: ROW('Budget Planning'!$C$65)
Name selected_period: Calculations!$E$20
Name selected_period_display: Calculations!$E$21
Name selected_year: Calculations!$E$19
Name Shift_late_income_starting_date: Settings!$E$18
Name Shift_late_income_status: Settings!$E$16
Name sort_max_row: 'Budget Dashboard'!$N1
Name sort_min_row: 'Budget Dashboard'!$M1
Name Starting_Year: Settings!$E$8
Name tracked: 'Budget Dashboard'!$K1
Name tracked_range: 'Budget Dashboard'!$O1
Name tracked_rank: 'Budget Dashboard'!$P1
Name type: 'Budget Dashboard'!$I1

Sheet Budget Dashboard
B2: Budget Dashboard
AQ5: Year
AN6: Select the year to view -> | AQ6: Current Year
AQ8: Period
AN9: Select the period to view -> | AQ9: Total Year
Y11: ="Breakdown - " & IF(selected_period="Total Year", selected_year & " (Total Year)", selected_period_display & " " & selected_year) -> Breakdown - 2026 (Total Year) | AF11: ="Summary - " & IF(selected_period="Total Year", selected_year & " (Total Year)", selected_period_display & " " & selected_year) -> Summary - 2026 (Total Year)
C12: row_id | D12: header_row_id | E12: is_header | F12: is_cat | G12: is_total | H12: is_empty | I12: type | J12: item | K12: tracked | L12: budget | M12: sort_min_row | N12: sort_max_row | O12: tracked_range | P12: tracked_rank | Q12: budget_range | R12: budget_rank | S12: comb_rank | T12: comb_rank_range | U12: comb_rank_norm | V12: comb_rank_norm_run_range | W12: comb_rank_unique | X12: sorted_row_id [Lookup]
C13: {=income_header_row} -> 10 | D13: =IF(is_header,row_id, IF(NOT(is_empty),D12,-1)) -> 10 | E13: {=1*OR(row_id=income_header_row, row_id=expenses_header_row, row_id=savings_header_row)} -> 1 | F13: =1*NOT(OR(is_header, is_total, is_empty)) -> 0 | G13: {=1*OR(row_id=income_total_row, row_id=expenses_total_row, row_id=savings_total_row)} -> 0 | H13: =1*OR(row_id="/1", row_id="/2", row_id=-1) -> 0 | I13: {=IFERROR(INDEX('Budget Planning'!$C:$C, header_row_id),"")} -> Income | J13: {=IFERROR(INDEX('Budget Planning'!$C:$C, row_id), "")} -> Income | K13: {=IF( OR(is_header, is_empty, selected_period=""), "", IF( is_total, IF( selected_period="Total Year", SUMPRODUCT( Tracking[Amount] * (Tracking[Type]=type) * (YEAR(Tracking[Effective Date])=selected_year) ), SUMPRODUCT( Tracking[Amount] * (Tracking[Type]=type) * (YEAR(Tracking[Effective Date])=selected_year) * (MONTH(Tracking[Effective Date])=selected_period) ) ), IF( selected_period="Total Year", SUMPRODUCT( Tracking[Amount] * (Tracking[Type]=type) * (Tracking[Category]=item) * (YEAR(Tracking[Effective Date])=selected_year) ), SUMPRODUCT( Tracking[Amount] * (Tracking[Type]=type) * (Tracking[Category]=item) * (YEAR(Tracking[Effective Date])=selected_year) * (MONTH(Tracking[Effective Date])=selected_period) ) ) ) )} | L13: {=IF( OR(is_header, is_empty), "", INDEX( 'Budget Planning'!$E:$FA, row_id, MATCH( IF( selected_period = "Total Year", selected_year, DATE(selected_year, selected_period, 1) ), 'Budget Planning'!$E$10:$FA$10, 0 ) ) )} | M13: {=IF( is_cat, IF( header_row_id = income_header_row, MATCH(income_min_row, $C:$C, 0), IF( header_row_id = expenses_header_row, MATCH(expenses_min_row, $C:$C, 0), IF( header_row_id = savings_header_row, MATCH(savings_min_row, $C:$C, 0), "" ) ) ), "" )} | N13: {=IF( is_cat, IF( header_row_id = income_header_row, MATCH(income_max_row, $C:$C, 0), IF( header_row_id = expenses_header_row, MATCH(expenses_max_row, $C:$C, 0), IF( header_row_id = savings_header_row, MATCH(savings_max_row, $C:$C, 0), "" ) ) ), "" )} | O13: =IF(is_cat, ADDRESS(sort_min_row, COLUMN(tracked)) &":" & ADDRESS(sort_max_row, COLUMN(tracked)), "") | P13: =IF(is_cat, RANK(tracked, INDIRECT(tracked_range), 0), "") | Q13: =IF(is_cat, ADDRESS(sort_min_row, COLUMN(budget)) &":" & ADDRESS(sort_max_row, COLUMN(budget)), "") | R13: =IF(is_cat, RANK(budget, INDIRECT(budget_range), 0), "") | S13: =IF(is_cat, _xlfn.NUMBERVALUE(tracked_rank & budget_rank), "") | T13: =IF(is_cat, ADDRESS(sort_min_row, COLUMN(comb_rank)) &":" & ADDRESS(sort_max_row, COLUMN(comb_rank)), "") | U13: =IF(is_cat,RANK(comb_rank,INDIRECT(comb_rank_range),1),"") | V13: =IF(is_cat, ADDRESS(sort_min_row, COLUMN(comb_rank_norm)) &":" & ADDRESS(ROW(), COLUMN(comb_rank_norm)), "") | W13: =IF(is_cat, comb_rank_norm + COUNTIF(INDIRECT(comb_rank_norm_run_range), comb_rank_norm)-1, "") | X13: =IF(is_cat, header_row_id + comb_rank_unique, row_id) -> 10 | Y13: =IF(is_empty, "", INDEX($J:$J, MATCH(row_id, $X:$X, 0))) -> Income | Z13: =IF(is_empty, "", IF(is_header, "Tracked", INDEX($K:$K, MATCH(row_id, $X:$X, 0)))) -> Tracked | AA13: =IF(is_empty, "", IF(is_header, "Budget", INDEX($L:$L, MATCH(row_id, $X:$X, 0)))) -> Budget | AB13: =IF(is_empty, "", IF(is_header, "% Compl.", IFERROR(out_tracked / out_budget, "-"))) -> % Compl. | AC13: =IF(is_empty, "", IF(is_header, "Remaining", IF(out_budget - out_tracked > 0, out_budget - out_tracked, 0))) -> Remaining | AD13: =IF(is_empty, "", IF(is_header, "Excess", IF(out_budget - out_tracked < 0, out_tracked - out_budget, 0))) -> Excess
C14: {=IF(C13=-1,-1, IF(C13<income_max_row, C13+1, IF(C13=income_max_row, income_total_row, IF(C13=income_total_row, "/1", IF(C13="/1", expenses_header_row, IF(C13<expenses_max_row, C13+1, IF(C13=expenses_max_row, expenses_total_row, IF(C13=expenses_total_row, "/2", IF(C13="/2", savings_header_row, IF(C13<savings_max_row, C13+1, IF(C13=savings_max_row, savings_total_row, -1)))))))))))} -> 11 | D14: =IF(is_header,row_id, IF(NOT(is_empty),D13,-1)) -> 10 | E14: {=1*OR(row_id=income_header_row, row_id=expenses_header_row, row_id=savings_header_row)} -> 0 | F14: =1*NOT(OR(is_header, is_total, is_empty)) -> 1 | G14: {=1*OR(row_id=income_total_row, row_id=expenses_total_row, row_id=savings_total_row)} -> 0 | H14: =1*OR(row_id="/1", row_id="/2", row_id=-1) -> 0 | I14: {=IFERROR(INDEX('Budget Planning'!$C:$C, header_row_id),"")} -> Income | J14: {=IFERROR(INDEX('Budget Planning'!$C:$C, row_id), "")} -> JPMC Salary | K14: {=IF( OR(is_header, is_empty, selected_period=""), "", IF( is_total, IF( selected_period="Total Year", SUMPRODUCT( Tracking[Amount] * (Tracking[Type]=type) * (YEAR(Tracking[Effective Date])=selected_year) ), SUMPRODUCT( Tracking[Amount] * (Tracking[Type]=type) * (YEAR(Tracking[Effective Date])=selected_year) * (MONTH(Tracking[Effective Date])=selected_period) ) ), IF( selected_period="Total Year", SUMPRODUCT( Tracking[Amount] * (Tracking[Type]=type) * (Tracking[Category]=item) * (YEAR(Tracking[Effective Date])=selected_year) ), SUMPRODUCT( Tracking[Amount] * (Tracking[Type]=type) * (Tracking[Category]=item) * (YEAR(Tracking[Effective Date])=selected_year) * (MONTH(Tracking[Effective Date])=selected_period) ) ) ) )} -> 291488 | L14: {=IF( OR(is_header, is_empty), "", INDEX( 'Budget Planning'!$E:$FA, row_id, MATCH( IF( selected_period = "Total Year", selected_year, DATE(selected_year, selected_period, 1) ), 'Budget Planning'!$E$10:$FA$10, 0 ) ) )} -> 291488 | M14: {=IF( is_cat, IF( header_row_id = income_header_row, MATCH(income_min_row, $C:$C, 0), IF( header_row_id = expenses_header_row, MATCH(expenses_min_row, $C:$C, 0), IF( header_row_id = savings_header_row, MATCH(savings_min_row, $C:$C, 0), "" ) ) ), "" )} -> 14 | N14: {=IF( is_cat, IF( header_row_id = income_header_row, MATCH(income_max_row, $C:$C, 0), IF( header_row_id = expenses_header_row, MATCH(expenses_max_row, $C:$C, 0), IF( header_row_id = savings_header_row, MATCH(savings_max_row, $C:$C, 0), "" ) ) ), "" )} -> 18 | O14: =IF(is_cat, ADDRESS(sort_min_row, COLUMN(tracked)) &":" & ADDRESS(sort_max_row, COLUMN(tracked)), "") -> $K$14:$K$18 | P14: =IF(is_cat, RANK(tracked, INDIRECT(tracked_range), 0), "") -> 1 | Q14: =IF(is_cat, ADDRESS(sort_min_row, COLUMN(budget)) &":" & ADDRESS(sort_max_row, COLUMN(budget)), "") -> $L$14:$L$18 | R14: =IF(is_cat, RANK(budget, INDIRECT(budget_range), 0), "") -> 1 | S14: =IF(is_cat, _xlfn.NUMBERVALUE(tracked_rank & budget_rank), "") -> 11 | T14: =IF(is_cat, ADDRESS(sort_min_row, COLUMN(comb_rank)) &":" & ADDRESS(sort_max_row, COLUMN(comb_rank)), "") -> $S$14:$S$18 | U14: =IF(is_cat,RANK(comb_rank,INDIRECT(comb_rank_range),1),"") -> 1 | V14: =IF(is_cat, ADDRESS(sort_min_row, COLUMN(comb_rank_norm)) &":" & ADDRESS(ROW(), COLUMN(comb_rank_norm)), "") -> $U$14:$U$14 | W14: =IF(is_cat, comb_rank_norm + COUNTIF(INDIRECT(comb_rank_norm_run_range), comb_rank_norm)-1, "") -> 1 | X14: =IF(is_cat, header_row_id + comb_rank_unique, row_id) -> 11 | Y14: =IF(is_empty, "", INDEX($J:$J, MATCH(row_id, $X:$X, 0))) -> JPMC Salary | Z14: =IF(is_empty, "", IF(is_header, "Tracked", INDEX($K:$K, MATCH(row_id, $X:$X, 0)))) -> 291488 | AA14: =IF(is_empty, "", IF(is_header, "Budget", INDEX($L:$L, MATCH(row_id, $X:$X, 0)))) -> 291488 | AB14: =IF(is_empty, "", IF(is_header, "% Compl.", IFERROR(out_tracked / out_budget, "-"))) -> 1 | AC14: =IF(is_empty, "", IF(is_header, "Remaining", IF(out_budget - out_tracked > 0, out_budget - out_tracked, 0))) -> 0 | AD14: =IF(is_empty, "", IF(is_header, "Excess", IF(out_budget - out_tracked < 0, out_tracked - out_budget, 0))) -> 0
C15: {=IF(C14=-1,-1, IF(C14<income_max_row, C14+1, IF(C14=income_max_row, income_total_row, IF(C14=income_total_row, "/1", IF(C14="/1", expenses_header_row, IF(C14<expenses_max_row, C14+1, IF(C14=expenses_max_row, expenses_total_row, IF(C14=expenses_total_row, "/2", IF(C14="/2", savings_header_row, IF(C14<savings_max_row, C14+1, IF(C14=savings_max_row, savings_total_row, -1)))))))))))} -> 12 | D15: =IF(is_header,row_id, IF(NOT(is_empty),D14,-1)) -> 10 | E15: {=1*OR(row_id=income_header_row, row_id=expenses_header_row, row_id=savings_header_row)} -> 0 | F15: =1*NOT(OR(is_header, is_total, is_empty)) -> 1 | G15: {=1*OR(row_id=income_total_row, row_id=expenses_total_row, row_id=savings_total_row)} -> 0 | H15: =1*OR(row_id="/1", row_id="/2", row_id=-1) -> 0 | I15: {=IFERROR(INDEX('Budget Planning'!$C:$C, header_row_id),"")} -> Income | J15: {=IFERROR(INDEX('Budget Planning'!$C:$C, row_id), "")} -> JPMC Bonus | K15: {=IF( OR(is_header, is_empty, selected_period=""), "", IF( is_total, IF( selected_period="Total Year", SUMPRODUCT( Tracking[Amount] * (Tracking[Type]=type) * (YEAR(Tracking[Effective Date])=selected_year) ), SUMPRODUCT( Tracking[Amount] * (Tracking[Type]=type) * (YEAR(Tracking[Effective Date])=selected_year) * (MONTH(Tracking[Effective Date])=selected_period) ) ), IF( selected_period="Total Year", SUMPRODUCT( Tracking[Amount] * (Tracking[Type]=type) * (Tracking[Category]=item) * (YEAR(Tracking[Effective Date])=selected_year) ), SUMPRODUCT( Tracking[Amount] * (Tracking[Type]=type) * (Tracking[Category]=item) * (YEAR(Tracking[Effective Date])=selected_year) * (MONTH(Tracking[Effective Date])=selected_period) ) ) ) )} -> 0 | L15: {=IF( OR(is_header, is_empty), "", INDEX( 'Budget Planning'!$E:$FA, row_id, MATCH( IF( selected_period = "Total Year", selected_year, DATE(selected_year, selected_period, 1) ), 'Budget Planning'!$E$10:$FA$10, 0 ) ) )} -> 0 | M15: {=IF( is_cat, IF( header_row_id = income_header_row, MATCH(income_min_row, $C:$C, 0), IF( header_row_id = expenses_header_row, MATCH(expenses_min_row, $C:$C, 0), IF( header_row_id = savings_header_row, MATCH(savings_min_row, $C:$C, 0), "" ) ) ), "" )} -> 14 | N15: {=IF( is_cat, IF( header_row_id = income_header_row, MATCH(income_max_row, $C:$C, 0), IF( header_row_id = expenses_header_row, MATCH(expenses_max_row, $C:$C, 0), IF( header_row_id = savings_header_row, MATCH(savings_max_row, $C:$C, 0), "" ) ) ), "" )} -> 18 | O15: =IF(is_cat, ADDRESS(sort_min_row, COLUMN(tracked)) &":" & ADDRESS(sort_max_row, COLUMN(tracked)), "") -> $K$14:$K$18 | P15: =IF(is_cat, RANK(tracked, INDIRECT(tracked_range), 0), "") -> 2 | Q15: =IF(is_cat, ADDRESS(sort_min_row, COLUMN(budget)) &":" & ADDRESS(sort_max_row, COLUMN(budget)), "") -> $L$14:$L$18 | R15: =IF(is_cat, RANK(budget, INDIRECT(budget_range), 0), "") -> 3 | S15: =IF(is_cat, _xlfn.NUMBERVALUE(tracked_rank & budget_rank), "") -> 23 | T15: =IF(is_cat, ADDRESS(sort_min_row, COLUMN(comb_rank)) &":" & ADDRESS(sort_max_row, COLUMN(comb_rank)), "") -> $S$14:$S$18 | U15: =IF(is_cat,RANK(comb_rank,INDIRECT(comb_rank_range),1),"") -> 3 | V15: =IF(is_cat, ADDRESS(sort_min_row, COLUMN(comb_rank_norm)) &":" & ADDRESS(ROW(), COLUMN(comb_rank_norm)), "") -> $U$14:$U$15 | W15: =IF(is_cat, comb_rank_norm + COUNTIF(INDIRECT(comb_rank_norm_run_range), comb_rank_norm)-1, "") -> 3 | X15: =IF(is_cat, header_row_id + comb_rank_unique, row_id) -> 13 | Y15: =IF(is_empty, "", INDEX($J:$J, MATCH(row_id, $X:$X, 0))) -> One Time Income | Z15: =IF(is_empty, "", IF(is_header, "Tracked", INDEX($K:$K, MATCH(row_id, $X:$X, 0)))) -> 0 | AA15: =IF(is_empty, "", IF(is_header, "Budget", INDEX($L:$L, MATCH(row_id, $X:$X, 0)))) -> 2100 | AB15: =IF(is_empty, "", IF(is_header, "% Compl.", IFERROR(out_tracked / out_budget, "-"))) -> 0 | AC15: =IF(is_empty, "", IF(is_header, "Remaining", IF(out_budget - out_tracked > 0, out_budget - out_tracked, 0))) -> 2100 | AD15: =IF(is_empty, "", IF(is_header, "Excess", IF(out_budget - out_tracked < 0, out_tracked - out_budget, 0))) -> 0
C16: {=IF(C15=-1,-1, IF(C15<income_max_row, C15+1, IF(C15=income_max_row, income_total_row, IF(C15=income_total_row, "/1", IF(C15="/1", expenses_header_row, IF(C15<expenses_max_row, C15+1, IF(C15=expenses_max_row, expenses_total_row, IF(C15=expenses_total_row, "/2", IF(C15="/2", savings_header_row, IF(C15<savings_max_row, C15+1, IF(C15=savings_max_row, savings_total_row, -1)))))))))))} -> 13 | D16: =IF(is_header,row_id, IF(NOT(is_empty),D15,-1)) -> 10 | E16: {=1*OR(row_id=income_header_row, row_id=expenses_header_row, row_id=savings_header_row)} -> 0 | F16: =1*NOT(OR(is_header, is_total, is_empty)) -> 1 | G16: {=1*OR(row_id=income_total_row, row_id=expenses_total_row, row_id=savings_total_row)} -> 0 | H16: =1*OR(row_id="/1", row_id="/2", row_id=-1) -> 0 | I16: {=IFERROR(INDEX('Budget Planning'!$C:$C, header_row_id),"")} -> Income | J16: {=IFERROR(INDEX('Budget Planning'!$C:$C, row_id), "")} -> Side Hustle | K16: {=IF( OR(is_header, is_empty, selected_period=""), "", IF( is_total, IF( selected_period="Total Year", SUMPRODUCT( Tracking[Amount] * (Tracking[Type]=type) * (YEAR(Tracking[Effective Date])=selected_year) ), SUMPRODUCT( Tracking[Amount] * (Tracking[Type]=type) * (YEAR(Tracking[Effective Date])=selected_year) * (MONTH(Tracking[Effective Date])=selected_period) ) ), IF( selected_period="Total Year", SUMPRODUCT( Tracking[Amount] * (Tracking[Type]=type) * (Tracking[Category]=item) * (YEAR(Tracking[Effective Date])=selected_year) ), SUMPRODUCT( Tracking[Amount] * (Tracking[Type]=type) * (Tracking[Category]=item) * (YEAR(Tracking[Effective Date])=selected_year) * (MONTH(Tracking[Effective Date])=selected_period) ) ) ) )} -> 0 | L16: {=IF( OR(is_header, is_empty), "", INDEX( 'Budget Planning'!$E:$FA, row_id, MATCH( IF( selected_period = "Total Year", selected_year, DATE(selected_year, selected_period, 1) ), 'Budget Planning'!$E$10:$FA$10, 0 ) ) )} -> 0 | M16: {=IF( is_cat, IF( header_row_id = income_header_row, MATCH(income_min_row, $C:$C, 0), IF( header_row_id = expenses_header_row, MATCH(expenses_min_row, $C:$C, 0), IF( header_row_id = savings_header_row, MATCH(savings_min_row, $C:$C, 0), "" ) ) ), "" )} -> 14 | N16: {=IF( is_cat, IF( header_row_id = income_header_row, MATCH(income_max_row, $C:$C, 0), IF( header_row_id = expenses_header_row, MATCH(expenses_max_row, $C:$C, 0), IF( header_row_id = savings_header_row, MATCH(savings_max_row, $C:$C, 0), "" ) ) ), "" )} -> 18 | O16: =IF(is_cat, ADDRESS(sort_min_row, COLUMN(tracked)) &":" & ADDRESS(sort_max_row, COLUMN(tracked)), "") -> $K$14:$K$18 | P16: =IF(is_cat, RANK(tracked, INDIRECT(tracked_range), 0), "") -> 2 | Q16: =IF(is_cat, ADDRESS(sort_min_row, COLUMN(budget)) &":" & ADDRESS(sort_max_row, COLUMN(budget)), "") -> $L$14:$L$18 | R16: =IF(is_cat, RANK(budget, INDIRECT(budget_range), 0), "") -> 3 | S16: =IF(is_cat, _xlfn.NUMBERVALUE(tracked_rank & budget_rank), "") -> 23 | T16: =IF(is_cat, ADDRESS(sort_min_row, COLUMN(comb_rank)) &":" & ADDRESS(sort_max_row, COLUMN(comb_rank)), "") -> $S$14:$S$18 | U16: =IF(is_cat,RANK(comb_rank,INDIRECT(comb_rank_range),1),"") -> 3 | V16: =IF(is_cat, ADDRESS(sort_min_row, COLUMN(comb_rank_norm)) &":" & ADDRESS(ROW(), COLUMN(comb_rank_norm)), "") -> $U$14:$U$16 | W16: =IF(is_cat, comb_rank_norm + COUNTIF(INDIRECT(comb_rank_norm_run_range), comb_rank_norm)-1, "") -> 4 | X16: =IF(is_cat, header_row_id + comb_rank_unique, row_id) -> 14 | Y16: =IF(is_empty, "", INDEX($J:$J, MATCH(row_id, $X:$X, 0))) -> JPMC Bonus | Z16: =IF(is_empty, "", IF(is_header, "Tracked", INDEX($K:$K, MATCH(row_id, $X:$X, 0)))) -> 0 | AA16: =IF(is_empty, "", IF(is_header, "Budget", INDEX($L:$L, MATCH(row_id, $X:$X, 0)))) -> 0 | AB16: =IF(is_empty, "", IF(is_header, "% Compl.", IFERROR(out_tracked / out_budget, "-"))) -> - | AC16: =IF(is_empty, "", IF(is_header, "Remaining", IF(out_budget - out_tracked > 0, out_budget - out_tracked, 0))) -> 0 | AD16: =IF(is_empty, "", IF(is_header, "Excess", IF(out_budget - out_tracked < 0, out_tracked - out_budget, 0))) -> 0 | AI16: =Calculations!E35 -> JPMC Salary | AJ16: =Calculations!F35 -> 291488
C17: {=IF(C16=-1,-1, IF(C16<income_max_row, C16+1, IF(C16=income_max_row, income_total_row, IF(C16=income_total_row, "/1", IF(C16="/1", expenses_header_row, IF(C16<expenses_max_row, C16+1, IF(C16=expenses_max_row, expenses_total_row, IF(C16=expenses_total_row, "/2", IF(C16="/2", savings_header_row, IF(C16<savings_max_row, C16+1, IF(C16=savings_max_row, savings_total_row, -1)))))))))))} -> 14 | D17: =IF(is_header,row_id, IF(NOT(is_empty),D16,-1)) -> 10 | E17: {=1*OR(row_id=income_header_row, row_id=expenses_header_row, row_id=savings_header_row)} -> 0 | F17: =1*NOT(OR(is_header, is_total, is_empty)) -> 1 | G17: {=1*OR(row_id=income_total_row, row_id=expenses_total_row, row_id=savings_total_row)} -> 0 | H17: =1*OR(row_id="/1", row_id="/2", row_id=-1) -> 0 | I17: {=IFERROR(INDEX('Budget Planning'!$C:$C, header_row_id),"")} -> Income | J17: {=IFERROR(INDEX('Budget Planning'!$C:$C, row_id), "")} -> Bank Interest | K17: {=IF( OR(is_header, is_empty, selected_period=""), "", IF( is_total, IF( selected_period="Total Year", SUMPRODUCT( Tracking[Amount] * (Tracking[Type]=type) * (YEAR(Tracking[Effective Date])=selected_year) ), SUMPRODUCT( Tracking[Amount] * (Tracking[Type]=type) * (YEAR(Tracking[Effective Date])=selected_year) * (MONTH(Tracking[Effective Date])=selected_period) ) ), IF( selected_period="Total Year", SUMPRODUCT( Tracking[Amount] * (Tracking[Type]=type) * (Tracking[Category]=item) * (YEAR(Tracking[Effective Date])=selected_year) ), SUMPRODUCT( Tracking[Amount] * (Tracking[Type]=type) * (Tracking[Category]=item) * (YEAR(Tracking[Effective Date])=selected_year) * (MONTH(Tracking[Effective Date])=selected_period) ) ) ) )} -> 0 | L17: {=IF( OR(is_header, is_empty), "", INDEX( 'Budget Planning'!$E:$FA, row_id, MATCH( IF( selected_period = "Total Year", selected_year, DATE(selected_year, selected_period, 1) ), 'Budget Planning'!$E$10:$FA$10, 0 ) ) )} -> 0 | M17: {=IF( is_cat, IF( header_row_id = income_header_row, MATCH(income_min_row, $C:$C, 0), IF( header_row_id = expenses_header_row, MATCH(expenses_min_row, $C:$C, 0), IF( header_row_id = savings_header_row, MATCH(savings_min_row, $C:$C, 0), "" ) ) ), "" )} -> 14 | N17: {=IF( is_cat, IF( header_row_id = income_header_row, MATCH(income_max_row, $C:$C, 0), IF( header_row_id = expenses_header_row, MATCH(expenses_max_row, $C:$C, 0), IF( header_row_id = savings_header_row, MATCH(savings_max_row, $C:$C, 0), "" ) ) ), "" )} -> 18 | O17: =IF(is_cat, ADDRESS(sort_min_row, COLUMN(tracked)) &":" & ADDRESS(sort_max_row, COLUMN(tracked)), "") -> $K$14:$K$18 | P17: =IF(is_cat, RANK(tracked, INDIRECT(tracked_range), 0), "") -> 2 | Q17: =IF(is_cat, ADDRESS(sort_min_row, COLUMN(budget)) &":" & ADDRESS(sort_max_row, COLUMN(budget)), "") -> $L$14:$L$18 | R17: =IF(is_cat, RANK(budget, INDIRECT(budget_range), 0), "") -> 3 | S17: =IF(is_cat, _xlfn.NUMBERVALUE(tracked_rank & budget_rank), "") -> 23 | T17: =IF(is_cat, ADDRESS(sort_min_row, COLUMN(comb_rank)) &":" & ADDRESS(sort_max_row, COLUMN(comb_rank)), "") -> $S$14:$S$18 | U17: =IF(is_cat,RANK(comb_rank,INDIRECT(comb_rank_range),1),"") -> 3 | V17: =IF(is_cat, ADDRESS(sort_min_row, COLUMN(comb_rank_norm)) &":" & ADDRESS(ROW(), COLUMN(comb_rank_norm)), "") -> $U$14:$U$17 | W17: =IF(is_cat, comb_rank_norm + COUNTIF(INDIRECT(comb_rank_norm_run_range), comb_rank_norm)-1, "") -> 5 | X17: =IF(is_cat, header_row_id + comb_rank_unique, row_id) -> 15 | Y17: =IF(is_empty, "", INDEX($J:$J, MATCH(row_id, $X:$X, 0))) -> Side Hustle | Z17: =IF(is_empty, "", IF(is_header, "Tracked", INDEX($K:$K, MATCH(row_id, $X:$X, 0)))) -> 0 | AA17: =IF(is_empty, "", IF(is_header, "Budget", INDEX($L:$L, MATCH(row_id, $X:$X, 0)))) -> 0 | AB17: =IF(is_empty, "", IF(is_header, "% Compl.", IFERROR(out_tracked / out_budget, "-"))) -> - | AC17: =IF(is_empty, "", IF(is_header, "Remaining", IF(out_budget - out_tracked > 0, out_budget - out_tracked, 0))) -> 0 | AD17: =IF(is_empty, "", IF(is_header, "Excess", IF(out_budget - out_tracked < 0, out_tracked - out_budget, 0))) -> 0 | AI17: =Calculations!E36 | AJ17: =Calculations!F36
C18: {=IF(C17=-1,-1, IF(C17<income_max_row, C17+1, IF(C17=income_max_row, income_total_row, IF(C17=income_total_row, "/1", IF(C17="/1", expenses_header_row, IF(C17<expenses_max_row, C17+1, IF(C17=expenses_max_row, expenses_total_row, IF(C17=expenses_total_row, "/2", IF(C17="/2", savings_header_row, IF(C17<savings_max_row, C17+1, IF(C17=savings_max_row, savings_total_row, -1)))))))))))} -> 15 | D18: =IF(is_header,row_id, IF(NOT(is_empty),D17,-1)) -> 10 | E18: {=1*OR(row_id=income_header_row, row_id=expenses_header_row, row_id=savings_header_row)} -> 0 | F18: =1*NOT(OR(is_header, is_total, is_empty)) -> 1 | G18: {=1*OR(row_id=income_total_row, row_id=expenses_total_row, row_id=savings_total_row)} -> 0 | H18: =1*OR(row_id="/1", row_id="/2", row_id=-1) -> 0 | I18: {=IFERROR(INDEX('Budget Planning'!$C:$C, header_row_id),"")} -> Income | J18: {=IFERROR(INDEX('Budget Planning'!$C:$C, row_id), "")} -> One Time Income | K18: {=IF( OR(is_header, is_empty, selected_period=""), "", IF( is_total, IF( selected_period="Total Year", SUMPRODUCT( Tracking[Amount] * (Tracking[Type]=type) * (YEAR(Tracking[Effective Date])=selected_year) ), SUMPRODUCT( Tracking[Amount] * (Tracking[Type]=type) * (YEAR(Tracking[Effective Date])=selected_year) * (MONTH(Tracking[Effective Date])=selected_period) ) ), IF( selected_period="Total Year", SUMPRODUCT( Tracking[Amount] * (Tracking[Type]=type) * (Tracking[Category]=item) * (YEAR(Tracking[Effective Date])=selected_year) ), SUMPRODUCT( Tracking[Amount] * (Tracking[Type]=type) * (Tracking[Category]=item) * (YEAR(Tracking[Effective Date])=selected_year) * (MONTH(Tracking[Effective Date])=selected_period) ) ) ) )} -> 0 | L18: {=IF( OR(is_header, is_empty), "", INDEX( 'Budget Planning'!$E:$FA, row_id, MATCH( IF( selected_period = "Total Year", selected_year, DATE(selected_year, selected_period, 1) ), 'Budget Planning'!$E$10:$FA$10, 0 ) ) )} -> 2100 | M18: {=IF( is_cat, IF( header_row_id = income_header_row, MATCH(income_min_row, $C:$C, 0), IF( header_row_id = expenses_header_row, MATCH(expenses_min_row, $C:$C, 0), IF( header_row_id = savings_header_row, MATCH(savings_min_row, $C:$C, 0), "" ) ) ), "" )} -> 14 | N18: {=IF( is_cat, IF( header_row_id = income_header_row, MATCH(income_max_row, $C:$C, 0), IF( header_row_id = expenses_header_row, MATCH(expenses_max_row, $C:$C, 0), IF( header_row_id = savings_header_row, MATCH(savings_max_row, $C:$C, 0), "" ) ) ), "" )} -> 18 | O18: =IF(is_cat, ADDRESS(sort_min_row, COLUMN(tracked)) &":" & ADDRESS(sort_max_row, COLUMN(tracked)), "") -> $K$14:$K$18 | P18: =IF(is_cat, RANK(tracked, INDIRECT(tracked_range), 0), "") -> 2 | Q18: =IF(is_cat, ADDRESS(sort_min_row, COLUMN(budget)) &":" & ADDRESS(sort_max_row, COLUMN(budget)), "") -> $L$14:$L$18 | R18: =IF(is_cat, RANK(budget, INDIRECT(budget_range), 0), "") -> 2 | S18: =IF(is_cat, _xlfn.NUMBERVALUE(tracked_rank & budget_rank), "") -> 22 | T18: =IF(is_cat, ADDRESS(sort_min_row, COLUMN(comb_rank)) &":" & ADDRESS(sort_max_row, COLUMN(comb_rank)), "") -> $S$14:$S$18 | U18: =IF(is_cat,RANK(comb_rank,INDIRECT(comb_rank_range),1),"") -> 2 | V18: =IF(is_cat, ADDRESS(sort_min_row, COLUMN(comb_rank_norm)) &":" & ADDRESS(ROW(), COLUMN(comb_rank_norm)), "") -> $U$14:$U$18 | W18: =IF(is_cat, comb_rank_norm + COUNTIF(INDIRECT(comb_rank_norm_run_range), comb_rank_norm)-1, "") -> 2 | X18: =IF(is_cat, header_row_id + comb_rank_unique, row_id) -> 12 | Y18: =IF(is_empty, "", INDEX($J:$J, MATCH(row_id, $X:$X, 0))) -> Bank Interest | Z18: =IF(is_empty, "", IF(is_header, "Tracked", INDEX($K:$K, MATCH(row_id, $X:$X, 0)))) -> 0 | AA18: =IF(is_empty, "", IF(is_header, "Budget", INDEX($L:$L, MATCH(row_id, $X:$X, 0)))) -> 0 | AB18: =IF(is_empty, "", IF(is_header, "% Compl.", IFERROR(out_tracked / out_budget, "-"))) -> - | AC18: =IF(is_empty, "", IF(is_header, "Remaining", IF(out_budget - out_tracked > 0, out_budget - out_tracked, 0))) -> 0 | AD18: =IF(is_empty, "", IF(is_header, "Excess", IF(out_budget - out_tracked < 0, out_tracked - out_budget, 0))) -> 0 | AI18: =Calculations!E37 | AJ18: =Calculations!F37
C19: {=IF(C18=-1,-1, IF(C18<income_max_row, C18+1, IF(C18=income_max_row, income_total_row, IF(C18=income_total_row, "/1", IF(C18="/1", expenses_header_row, IF(C18<expenses_max_row, C18+1, IF(C18=expenses_max_row, expenses_total_row, IF(C18=expenses_total_row, "/2", IF(C18="/2", savings_header_row, IF(C18<savings_max_row, C18+1, IF(C18=savings_max_row, savings_total_row, -1)))))))))))} -> 27 | D19: =IF(is_header,row_id, IF(NOT(is_empty),D18,-1)) -> 10 | E19: {=1*OR(row_id=income_header_row, row_id=expenses_header_row, row_id=savings_header_row)} -> 0 | F19: =1*NOT(OR(is_header, is_total, is_empty)) -> 0 | G19: {=1*OR(row_id=income_total_row, row_id=expenses_total_row, row_id=savings_total_row)} -> 1 | H19: =1*OR(row_id="/1", row_id="/2", row_id=-1) -> 0 | I19: {=IFERROR(INDEX('Budget Planning'!$C:$C, header_row_id),"")} -> Income | J19: {=IFERROR(INDEX('Budget Planning'!$C:$C, row_id), "")} -> Total | K19: {=IF( OR(is_header, is_empty, selected_period=""), "", IF( is_total, IF( selected_period="Total Year", SUMPRODUCT( Tracking[Amount] * (Tracking[Type]=type) * (YEAR(Tracking[Effective Date])=selected_year) ), SUMPRODUCT( Tracking[Amount] * (Tracking[Type]=type) * (YEAR(Tracking[Effective Date])=selected_year) * (MONTH(Tracking[Effective Date])=selected_period) ) ), IF( selected_period="Total Year", SUMPRODUCT( Tracking[Amount] * (Tracking[Type]=type) * (Tracking[Category]=item) * (YEAR(Tracking[Effective Date])=selected_year) ), SUMPRODUCT( Tracking[Amount] * (Tracking[Type]=type) * (Tracking[Category]=item) * (YEAR(Tracking[Effective Date])=selected_year) * (MONTH(Tracking[Effective Date])=selected_period) ) ) ) )} -> 291488 | L19: {=IF( OR(is_header, is_empty), "", INDEX( 'Budget Planning'!$E:$FA, row_id, MATCH( IF( selected_period = "Total Year", selected_year, DATE(selected_year, selected_period, 1) ), 'Budget Planning'!$E$10:$FA$10, 0 ) ) )} -> 293588 | M19: {=IF( is_cat, IF( header_row_id = income_header_row, MATCH(income_min_row, $C:$C, 0), IF( header_row_id = expenses_header_row, MATCH(expenses_min_row, $C:$C, 0), IF( header_row_id = savings_header_row, MATCH(savings_min_row, $C:$C, 0), "" ) ) ), "" )} | N19: {=IF( is_cat, IF( header_row_id = income_header_row, MATCH(income_max_row, $C:$C, 0), IF( header_row_id = expenses_header_row, MATCH(expenses_max_row, $C:$C, 0), IF( header_row_id = savings_header_row, MATCH(savings_max_row, $C:$C, 0), "" ) ) ), "" )} | O19: =IF(is_cat, ADDRESS(sort_min_row, COLUMN(tracked)) &":" & ADDRESS(sort_max_row, COLUMN(tracked)), "") | P19: =IF(is_cat, RANK(tracked, INDIRECT(tracked_range), 0), "") | Q19: =IF(is_cat, ADDRESS(sort_min_row, COLUMN(budget)) &":" & ADDRESS(sort_max_row, COLUMN(budget)), "") | R19: =IF(is_cat, RANK(budget, INDIRECT(budget_range), 0), "") | S19: =IF(is_cat, _xlfn.NUMBERVALUE(tracked_rank & budget_rank), "") | T19: =IF(is_cat, ADDRESS(sort_min_row, COLUMN(comb_rank)) &":" & ADDRESS(sort_max_row, COLUMN(comb_rank)), "") | U19: =IF(is_cat,RANK(comb_rank,INDIRECT(comb_rank_range),1),"") | V19: =IF(is_cat, ADDRESS(sort_min_row, COLUMN(comb_rank_norm)) &":" & ADDRESS(ROW(), COLUMN(comb_rank_norm)), "") | W19: =IF(is_cat, comb_rank_norm + COUNTIF(INDIRECT(comb_rank_norm_run_range), comb_rank_norm)-1, "") | X19: =IF(is_cat, header_row_id + comb_rank_unique, row_id) -> 27 | Y19: =IF(is_empty, "", INDEX($J:$J, MATCH(row_id, $X:$X, 0))) -> Total | Z19: =IF(is_empty, "", IF(is_header, "Tracked", INDEX($K:$K, MATCH(row_id, $X:$X, 0)))) -> 291488 | AA19: =IF(is_empty, "", IF(is_header, "Budget", INDEX($L:$L, MATCH(row_id, $X:$X, 0)))) -> 293588 | AB19: =IF(is_empty, "", IF(is_header, "% Compl.", IFERROR(out_tracked / out_budget, "-"))) -> 0.99284712 | AC19: =IF(is_empty, "", IF(is_header, "Remaining", IF(out_budget - out_tracked > 0, out_budget - out_tracked, 0))) -> 2100 | AD19: =IF(is_empty, "", IF(is_header, "Excess", IF(out_budget - out_tracked < 0, out_tracked - out_budget, 0))) -> 0 | AI19: =Calculations!E38 | AJ19: =Calculations!F38
C20: {=IF(C19=-1,-1, IF(C19<income_max_row, C19+1, IF(C19=income_max_row, income_total_row, IF(C19=income_total_row, "/1", IF(C19="/1", expenses_header_row, IF(C19<expenses_max_row, C19+1, IF(C19=expenses_max_row, expenses_total_row, IF(C19=expenses_total_row, "/2", IF(C19="/2", savings_header_row, IF(C19<savings_max_row, C19+1, IF(C19=savings_max_row, savings_total_row, -1)))))))))))} -> /1 | D20: =IF(is_header,row_id, IF(NOT(is_empty),D19,-1)) -> -1 | E20: {=1*OR(row_id=income_header_row, row_id=expenses_header_row, row_id=savings_header_row)} -> 0 | F20: =1*NOT(OR(is_header, is_total, is_empty)) -> 0 | G20: {=1*OR(row_id=income_total_row, row_id=expenses_total_row, row_id=savings_total_row)} -> 0 | H20: =1*OR(row_id="/1", row_id="/2", row_id=-1) -> 1 | I20: {=IFERROR(INDEX('Budget Planning'!$C:$C, header_row_id),"")} | J20: {=IFERROR(INDEX('Budget Planning'!$C:$C, row_id), "")} | K20: {=IF( OR(is_header, is_empty, selected_period=""), "", IF( is_total, IF( selected_period="Total Year", SUMPRODUCT( Tracking[Amount] * (Tracking[Type]=type) * (YEAR(Tracking[Effective Date])=selected_year) ), SUMPRODUCT( Tracking[Amount] * (Tracking[Type]=type) * (YEAR(Tracking[Effective Date])=selected_year) * (MONTH(Tracking[Effective Date])=selected_period) ) ), IF( selected_period="Total Year", SUMPRODUCT( Tracking[Amount] * (Tracking[Type]=type) * (Tracking[Category]=item) * (YEAR(Tracking[Effective Date])=selected_year) ), SUMPRODUCT( Tracking[Amount] * (Tracking[Type]=type) * (Tracking[Category]=item) * (YEAR(Tracking[Effective Date])=selected_year) * (MONTH(Tracking[Effective Date])=selected_period) ) ) ) )} | L20: {=IF( OR(is_header, is_empty), "", INDEX( 'Budget Planning'!$E:$FA, row_id, MATCH( IF( selected_period = "Total Year", selected_year, DATE(selected_year, selected_period, 1) ), 'Budget Planning'!$E$10:$FA$10, 0 ) ) )} | M20: {=IF( is_cat, IF( header_row_id = income_header_row, MATCH(income_min_row, $C:$C, 0), IF( header_row_id = expenses_header_row, MATCH(expenses_min_row, $C:$C, 0), IF( header_row_id = savings_header_row, MATCH(savings_min_row, $C:$C, 0), "" ) ) ), "" )} | N20: {=IF( is_cat, IF( header_row_id = income_header_row, MATCH(income_max_row, $C:$C, 0), IF( header_row_id = expenses_header_row, MATCH(expenses_max_row, $C:$C, 0), IF( header_row_id = savings_header_row, MATCH(savings_max_row, $C:$C, 0), "" ) ) ), "" )} | O20: =IF(is_cat, ADDRESS(sort_min_row, COLUMN(tracked)) &":" & ADDRESS(sort_max_row, COLUMN(tracked)), "") | P20: =IF(is_cat, RANK(tracked, INDIRECT(tracked_range), 0), "") | Q20: =IF(is_cat, ADDRESS(sort_min_row, COLUMN(budget)) &":" & ADDRESS(sort_max_row, COLUMN(budget)), "") | R20: =IF(is_cat, RANK(budget, INDIRECT(budget_range), 0), "") | S20: =IF(is_cat, _xlfn.NUMBERVALUE(tracked_rank & budget_rank), "") | T20: =IF(is_cat, ADDRESS(sort_min_row, COLUMN(comb_rank)) &":" & ADDRESS(sort_max_row, COLUMN(comb_rank)), "") | U20: =IF(is_cat,RANK(comb_rank,INDIRECT(comb_rank_range),1),"") | V20: =IF(is_cat, ADDRESS(sort_min_row, COLUMN(comb_rank_norm)) &":" & ADDRESS(ROW(), COLUMN(comb_rank_norm)), "") | W20: =IF(is_cat, comb_rank_norm + COUNTIF(INDIRECT(comb_rank_norm_run_range), comb_rank_norm)-1, "") | X20: =IF(is_cat, header_row_id + comb_rank_unique, row_id) -> /1 | Y20: =IF(is_empty, "", INDEX($J:$J, MATCH(row_id, $X:$X, 0))) | Z20: =IF(is_empty, "", IF(is_header, "Tracked", INDEX($K:$K, MATCH(row_id, $X:$X, 0)))) | AA20: =IF(is_empty, "", IF(is_header, "Budget", INDEX($L:$L, MATCH(row_id, $X:$X, 0)))) | AB20: =IF(is_empty, "", IF(is_header, "% Compl.", IFERROR(out_tracked / out_budget, "-"))) | AC20: =IF(is_empty, "", IF(is_header, "Remaining", IF(out_budget - out_tracked > 0, out_budget - out_tracked, 0))) | AD20: =IF(is_empty, "", IF(is_header, "Excess", IF(out_budget - out_tracked < 0, out_tracked - out_budget, 0))) | AI20: =Calculations!E39 | AJ20: =Calculations!F39
C21: {=IF(C20=-1,-1, IF(C20<income_max_row, C20+1, IF(C20=income_max_row, income_total_row, IF(C20=income_total_row, "/1", IF(C20="/1", expenses_header_row, IF(C20<expenses_max_row, C20+1, IF(C20=expenses_max_row, expenses_total_row, IF(C20=expenses_total_row, "/2", IF(C20="/2", savings_header_row, IF(C20<savings_max_row, C20+1, IF(C20=savings_max_row, savings_total_row, -1)))))))))))} -> 29 | D21: =IF(is_header,row_id, IF(NOT(is_empty),D20,-1)) -> 29 | E21: {=1*OR(row_id=income_header_row, row_id=expenses_header_row, row_id=savings_header_row)} -> 1 | F21: =1*NOT(OR(is_header, is_total, is_empty)) -> 0 | G21: {=1*OR(row_id=income_total_row, row_id=expenses_total_row, row_id=savings_total_row)} -> 0 | H21: =1*OR(row_id="/1", row_id="/2", row_id=-1) -> 0 | I21: {=IFERROR(INDEX('Budget Planning'!$C:$C, header_row_id),"")} -> Expenses | J21: {=IFERROR(INDEX('Budget Planning'!$C:$C, row_id), "")} -> Expenses | K21: {=IF( OR(is_header, is_empty, selected_period=""), "", IF( is_total, IF( selected_period="Total Year", SUMPRODUCT( Tracking[Amount] * (Tracking[Type]=type) * (YEAR(Tracking[Effective Date])=selected_year) ), SUMPRODUCT( Tracking[Amount] * (Tracking[Type]=type) * (YEAR(Tracking[Effective Date])=selected_year) * (MONTH(Tracking[Effective Date])=selected_period) ) ), IF( selected_period="Total Year", SUMPRODUCT( Tracking[Amount] * (Tracking[Type]=type) * (Tracking[Category]=item) * (YEAR(Tracking[Effective Date])=selected_year) ), SUMPRODUCT( Tracking[Amount] * (Tracking[Type]=type) * (Tracking[Category]=item) * (YEAR(Tracking[Effective Date])=selected_year) * (MONTH(Tracking[Effective Date])=selected_period) ) ) ) )} | L21: {=IF( OR(is_header, is_empty), "", INDEX( 'Budget Planning'!$E:$FA, row_id, MATCH( IF( selected_period = "Total Year", selected_year, DATE(selected_year, selected_period, 1) ), 'Budget Planning'!$E$10:$FA$10, 0 ) ) )} | M21: {=IF( is_cat, IF( header_row_id = income_header_row, MATCH(income_min_row, $C:$C, 0), IF( header_row_id = expenses_header_row, MATCH(expenses_min_row, $C:$C, 0), IF( header_row_id = savings_header_row, MATCH(savings_min_row, $C:$C, 0), "" ) ) ), "" )} | N21: {=IF( is_cat, IF( header_row_id = income_header_row, MATCH(income_max_row, $C:$C, 0), IF( header_row_id = expenses_header_row, MATCH(expenses_max_row, $C:$C, 0), IF( header_row_id = savings_header_row, MATCH(savings_max_row, $C:$C, 0), "" ) ) ), "" )} | O21: =IF(is_cat, ADDRESS(sort_min_row, COLUMN(tracked)) &":" & ADDRESS(sort_max_row, COLUMN(tracked)), "") | P21: =IF(is_cat, RANK(tracked, INDIRECT(tracked_range), 0), "") | Q21: =IF(is_cat, ADDRESS(sort_min_row, COLUMN(budget)) &":" & ADDRESS(sort_max_row, COLUMN(budget)), "") | R21: =IF(is_cat, RANK(budget, INDIRECT(budget_range), 0), "") | S21: =IF(is_cat, _xlfn.NUMBERVALUE(tracked_rank & budget_rank), "") | T21: =IF(is_cat, ADDRESS(sort_min_row, COLUMN(comb_rank)) &":" & ADDRESS(sort_max_row, COLUMN(comb_rank)), "") | U21: =IF(is_cat,RANK(comb_rank,INDIRECT(comb_rank_range),1),"") | V21: =IF(is_cat, ADDRESS(sort_min_row, COLUMN(comb_rank_norm)) &":" & ADDRESS(ROW(), COLUMN(comb_rank_norm)), "") | W21: =IF(is_cat, comb_rank_norm + COUNTIF(INDIRECT(comb_rank_norm_run_range), comb_rank_norm)-1, "") | X21: =IF(is_cat, header_row_id + comb_rank_unique, row_id) -> 29 | Y21: =IF(is_empty, "", INDEX($J:$J, MATCH(row_id, $X:$X, 0))) -> Expenses | Z21: =IF(is_empty, "", IF(is_header, "Tracked", INDEX($K:$K, MATCH(row_id, $X:$X, 0)))) -> Tracked | AA21: =IF(is_empty, "", IF(is_header, "Budget", INDEX($L:$L, MATCH(row_id, $X:$X, 0)))) -> Budget | AB21: =IF(is_empty, "", IF(is_header, "% Compl.", IFERROR(out_tracked / out_budget, "-"))) -> % Compl. | AC21: =IF(is_empty, "", IF(is_header, "Remaining", IF(out_budget - out_tracked > 0, out_budget - out_tracked, 0))) -> Remaining | AD21: =IF(is_empty, "", IF(is_header, "Excess", IF(out_budget - out_tracked < 0, out_tracked - out_budget, 0))) -> Excess | AI21: =Calculations!E40 | AJ21: =Calculations!F40
C22: {=IF(C21=-1,-1, IF(C21<income_max_row, C21+1, IF(C21=income_max_row, income_total_row, IF(C21=income_total_row, "/1", IF(C21="/1", expenses_header_row, IF(C21<expenses_max_row, C21+1, IF(C21=expenses_max_row, expenses_total_row, IF(C21=expenses_total_row, "/2", IF(C21="/2", savings_header_row, IF(C21<savings_max_row, C21+1, IF(C21=savings_max_row, savings_total_row, -1)))))))))))} -> 30 | D22: =IF(is_header,row_id, IF(NOT(is_empty),D21,-1)) -> 29 | E22: {=1*OR(row_id=income_header_row, row_id=expenses_header_row, row_id=savings_header_row)} -> 0 | F22: =1*NOT(OR(is_header, is_total, is_empty)) -> 1 | G22: {=1*OR(row_id=income_total_row, row_id=expenses_total_row, row_id=savings_total_row)} -> 0 | H22: =1*OR(row_id="/1", row_id="/2", row_id=-1) -> 0 | I22: {=IFERROR(INDEX('Budget Planning'!$C:$C, header_row_id),"")} -> Expenses | J22: {=IFERROR(INDEX('Budget Planning'!$C:$C, row_id), "")} -> Rent | K22: {=IF( OR(is_header, is_empty, selected_period=""), "", IF( is_total, IF( selected_period="Total Year", SUMPRODUCT( Tracking[Amount] * (Tracking[Type]=type) * (YEAR(Tracking[Effective Date])=selected_year) ), SUMPRODUCT( Tracking[Amount] * (Tracking[Type]=type) * (YEAR(Tracking[Effective Date])=selected_year) * (MONTH(Tracking[Effective Date])=selected_period) ) ), IF( selected_period="Total Year", SUMPRODUCT( Tracking[Amount] * (Tracking[Type]=type) * (Tracking[Category]=item) * (YEAR(Tracking[Effective Date])=selected_year) ), SUMPRODUCT( Tracking[Amount] * (Tracking[Type]=type) * (Tracking[Category]=item) * (YEAR(Tracking[Effective Date])=selected_year) * (MONTH(Tracking[Effective Date])=selected_period) ) ) ) )} -> 70000 | L22: {=IF( OR(is_header, is_empty), "", INDEX( 'Budget Planning'!$E:$FA, row_id, MATCH( IF( selected_period = "Total Year", selected_year, DATE(selected_year, selected_period, 1) ), 'Budget Planning'!$E$10:$FA$10, 0 ) ) )} -> 70000 | M22: {=IF( is_cat, IF( header_row_id = income_header_row, MATCH(income_min_row, $C:$C, 0), IF( header_row_id = expenses_header_row, MATCH(expenses_min_row, $C:$C, 0), IF( header_row_id = savings_header_row, MATCH(savings_min_row, $C:$C, 0), "" ) ) ), "" )} -> 22 | N22: {=IF( is_cat, IF( header_row_id = income_header_row, MATCH(income_max_row, $C:$C, 0), IF( header_row_id = expenses_header_row, MATCH(expenses_max_row, $C:$C, 0), IF( header_row_id = savings_header_row, MATCH(savings_max_row, $C:$C, 0), "" ) ) ), "" )} -> 36 | O22: =IF(is_cat, ADDRESS(sort_min_row, COLUMN(tracked)) &":" & ADDRESS(sort_max_row, COLUMN(tracked)), "") -> $K$22:$K$36 | P22: =IF(is_cat, RANK(tracked, INDIRECT(tracked_range), 0), "") -> 1 | Q22: =IF(is_cat, ADDRESS(sort_min_row, COLUMN(budget)) &":" & ADDRESS(sort_max_row, COLUMN(budget)), "") -> $L$22:$L$36 | R22: =IF(is_cat, RANK(budget, INDIRECT(budget_range), 0), "") -> 1 | S22: =IF(is_cat, _xlfn.NUMBERVALUE(tracked_rank & budget_rank), "") -> 11 | T22: =IF(is_cat, ADDRESS(sort_min_row, COLUMN(comb_rank)) &":" & ADDRESS(sort_max_row, COLUMN(comb_rank)), "") -> $S$22:$S$36 | U22: =IF(is_cat,RANK(comb_rank,INDIRECT(comb_rank_range),1),"") -> 1 | V22: =IF(is_cat, ADDRESS(sort_min_row, COLUMN(comb_rank_norm)) &":" & ADDRESS(ROW(), COLUMN(comb_rank_norm)), "") -> $U$22:$U$22 | W22: =IF(is_cat, comb_rank_norm + COUNTIF(INDIRECT(comb_rank_norm_run_range), comb_rank_norm)-1, "") -> 1 | X22: =IF(is_cat, header_row_id + comb_rank_unique, row_id) -> 30 | Y22: =IF(is_empty, "", INDEX($J:$J, MATCH(row_id, $X:$X, 0))) -> Rent | Z22: =IF(is_empty, "", IF(is_header, "Tracked", INDEX($K:$K, MATCH(row_id, $X:$X, 0)))) -> 70000 | AA22: =IF(is_empty, "", IF(is_header, "Budget", INDEX($L:$L, MATCH(row_id, $X:$X, 0)))) -> 70000 | AB22: =IF(is_empty, "", IF(is_header, "% Compl.", IFERROR(out_tracked / out_budget, "-"))) -> 1 | AC22: =IF(is_empty, "", IF(is_header, "Remaining", IF(out_budget - out_tracked > 0, out_budget - out_tracked, 0))) -> 0 | AD22: =IF(is_empty, "", IF(is_header, "Excess", IF(out_budget - out_tracked < 0, out_tracked - out_budget, 0))) -> 0 | AI22: =Calculations!E41 -> Total | AJ22: =Calculations!F41 -> 291488
C23: {=IF(C22=-1,-1, IF(C22<income_max_row, C22+1, IF(C22=income_max_row, income_total_row, IF(C22=income_total_row, "/1", IF(C22="/1", expenses_header_row, IF(C22<expenses_max_row, C22+1, IF(C22=expenses_max_row, expenses_total_row, IF(C22=expenses_total_row, "/2", IF(C22="/2", savings_header_row, IF(C22<savings_max_row, C22+1, IF(C22=savings_max_row, savings_total_row, -1)))))))))))} -> 31 | D23: =IF(is_header,row_id, IF(NOT(is_empty),D22,-1)) -> 29 | E23: {=1*OR(row_id=income_header_row, row_id=expenses_header_row, row_id=savings_header_row)} -> 0 | F23: =1*NOT(OR(is_header, is_total, is_empty)) -> 1 | G23: {=1*OR(row_id=income_total_row, row_id=expenses_total_row, row_id=savings_total_row)} -> 0 | H23: =1*OR(row_id="/1", row_id="/2", row_id=-1) -> 0 | I23: {=IFERROR(INDEX('Budget Planning'!$C:$C, header_row_id),"")} -> Expenses | J23: {=IFERROR(INDEX('Budget Planning'!$C:$C, row_id), "")} -> Groceries | K23: {=IF( OR(is_header, is_empty, selected_period=""), "", IF( is_total, IF( selected_period="Total Year", SUMPRODUCT( Tracking[Amount] * (Tracking[Type]=type) * (YEAR(Tracking[Effective Date])=selected_year) ), SUMPRODUCT( Tracking[Amount] * (Tracking[Type]=type) * (YEAR(Tracking[Effective Date])=selected_year) * (MONTH(Tracking[Effective Date])=selected_period) ) ), IF( selected_period="Total Year", SUMPRODUCT( Tracking[Amount] * (Tracking[Type]=type) * (Tracking[Category]=item) * (YEAR(Tracking[Effective Date])=selected_year) ), SUMPRODUCT( Tracking[Amount] * (Tracking[Type]=type) * (Tracking[Category]=item) * (YEAR(Tracking[Effective Date])=selected_year) * (MONTH(Tracking[Effective Date])=selected_period) ) ) ) )} -> 0 | L23: {=IF( OR(is_header, is_empty), "", INDEX( 'Budget Planning'!$E:$FA, row_id, MATCH( IF( selected_period = "Total Year", selected_year, DATE(selected_year, selected_period, 1) ), 'Budget Planning'!$E$10:$FA$10, 0 ) ) )} -> 0 | M23: {=IF( is_cat, IF( header_row_id = income_header_row, MATCH(income_min_row, $C:$C, 0), IF( header_row_id = expenses_header_row, MATCH(expenses_min_row, $C:$C, 0), IF( header_row_id = savings_header_row, MATCH(savings_min_row, $C:$C, 0), "" ) ) ), "" )} -> 22 | N23: {=IF( is_cat, IF( header_row_id = income_header_row, MATCH(income_max_row, $C:$C, 0), IF( header_row_id = expenses_header_row, MATCH(expenses_max_row, $C:$C, 0), IF( header_row_id = savings_header_row, MATCH(savings_max_row, $C:$C, 0), "" ) ) ), "" )} -> 36 | O23: =IF(is_cat, ADDRESS(sort_min_row, COLUMN(tracked)) &":" & ADDRESS(sort_max_row, COLUMN(tracked)), "") -> $K$22:$K$36 | P23: =IF(is_cat, RANK(tracked, INDIRECT(tracked_range), 0), "") -> 2 | Q23: =IF(is_cat, ADDRESS(sort_min_row, COLUMN(budget)) &":" & ADDRESS(sort_max_row, COLUMN(budget)), "") -> $L$22:$L$36 | R23: =IF(is_cat, RANK(budget, INDIRECT(budget_range), 0), "") -> 3 | S23: =IF(is_cat, _xlfn.NUMBERVALUE(tracked_rank & budget_rank), "") -> 23 | T23: =IF(is_cat, ADDRESS(sort_min_row, COLUMN(comb_rank)) &":" & ADDRESS(sort_max_row, COLUMN(comb_rank)), "") -> $S$22:$S$36 | U23: =IF(is_cat,RANK(comb_rank,INDIRECT(comb_rank_range),1),"") -> 3 | V23: =IF(is_cat, ADDRESS(sort_min_row, COLUMN(comb_rank_norm)) &":" & ADDRESS(ROW(), COLUMN(comb_rank_norm)), "") -> $U$22:$U$23 | W23: =IF(is_cat, comb_rank_norm + COUNTIF(INDIRECT(comb_rank_norm_run_range), comb_rank_norm)-1, "") -> 3 | X23: =IF(is_cat, header_row_id + comb_rank_unique, row_id) -> 32 | Y23: =IF(is_empty, "", INDEX($J:$J, MATCH(row_id, $X:$X, 0))) -> CC Bill | Z23: =IF(is_empty, "", IF(is_header, "Tracked", INDEX($K:$K, MATCH(row_id, $X:$X, 0)))) -> 0 | AA23: =IF(is_empty, "", IF(is_header, "Budget", INDEX($L:$L, MATCH(row_id, $X:$X, 0)))) -> 44417 | AB23: =IF(is_empty, "", IF(is_header, "% Compl.", IFERROR(out_tracked / out_budget, "-"))) -> 0 | AC23: =IF(is_empty, "", IF(is_header, "Remaining", IF(out_budget - out_tracked > 0, out_budget - out_tracked, 0))) -> 44417 | AD23: =IF(is_empty, "", IF(is_header, "Excess", IF(out_budget - out_tracked < 0, out_tracked - out_budget, 0))) -> 0
C24: {=IF(C23=-1,-1, IF(C23<income_max_row, C23+1, IF(C23=income_max_row, income_total_row, IF(C23=income_total_row, "/1", IF(C23="/1", expenses_header_row, IF(C23<expenses_max_row, C23+1, IF(C23=expenses_max_row, expenses_total_row, IF(C23=expenses_total_row, "/2", IF(C23="/2", savings_header_row, IF(C23<savings_max_row, C23+1, IF(C23=savings_max_row, savings_total_row, -1)))))))))))} -> 32 | D24: =IF(is_header,row_id, IF(NOT(is_empty),D23,-1)) -> 29 | E24: {=1*OR(row_id=income_header_row, row_id=expenses_header_row, row_id=savings_header_row)} -> 0 | F24: =1*NOT(OR(is_header, is_total, is_empty)) -> 1 | G24: {=1*OR(row_id=income_total_row, row_id=expenses_total_row, row_id=savings_total_row)} -> 0 | H24: =1*OR(row_id="/1", row_id="/2", row_id=-1) -> 0 | I24: {=IFERROR(INDEX('Budget Planning'!$C:$C, header_row_id),"")} -> Expenses | J24: {=IFERROR(INDEX('Budget Planning'!$C:$C, row_id), "")} -> Transport | K24: {=IF( OR(is_header, is_empty, selected_period=""), "", IF( is_total, IF( selected_period="Total Year", SUMPRODUCT( Tracking[Amount] * (Tracking[Type]=type) * (YEAR(Tracking[Effective Date])=selected_year) ), SUMPRODUCT( Tracking[Amount] * (Tracking[Type]=type) * (YEAR(Tracking[Effective Date])=selected_year) * (MONTH(Tracking[Effective Date])=selected_period) ) ), IF( selected_period="Total Year", SUMPRODUCT( Tracking[Amount] * (Tracking[Type]=type) * (Tracking[Category]=item) * (YEAR(Tracking[Effective Date])=selected_year) ), SUMPRODUCT( Tracking[Amount] * (Tracking[Type]=type) * (Tracking[Category]=item) * (YEAR(Tracking[Effective Date])=selected_year) * (MONTH(Tracking[Effective Date])=selected_period) ) ) ) )} -> 0 | L24: {=IF( OR(is_header, is_empty), "", INDEX( 'Budget Planning'!$E:$FA, row_id, MATCH( IF( selected_period = "Total Year", selected_year, DATE(selected_year, selected_period, 1) ), 'Budget Planning'!$E$10:$FA$10, 0 ) ) )} -> 0 | M24: {=IF( is_cat, IF( header_row_id = income_header_row, MATCH(income_min_row, $C:$C, 0), IF( header_row_id = expenses_header_row, MATCH(expenses_min_row, $C:$C, 0), IF( header_row_id = savings_header_row, MATCH(savings_min_row, $C:$C, 0), "" ) ) ), "" )} -> 22 | N24: {=IF( is_cat, IF( header_row_id = income_header_row, MATCH(income_max_row, $C:$C, 0), IF( header_row_id = expenses_header_row, MATCH(expenses_max_row, $C:$C, 0), IF( header_row_id = savings_header_row, MATCH(savings_max_row, $C:$C, 0), "" ) ) ), "" )} -> 36 | O24: =IF(is_cat, ADDRESS(sort_min_row, COLUMN(tracked)) &":" & ADDRESS(sort_max_row, COLUMN(tracked)), "") -> $K$22:$K$36 | P24: =IF(is_cat, RANK(tracked, INDIRECT(tracked_range), 0), "") -> 2 | Q24: =IF(is_cat, ADDRESS(sort_min_row, COLUMN(budget)) &":" & ADDRESS(sort_max_row, COLUMN(budget)), "") -> $L$22:$L$36 | R24: =IF(is_cat, RANK(budget, INDIRECT(budget_range), 0), "") -> 3 | S24: =IF(is_cat, _xlfn.NUMBERVALUE(tracked_rank & budget_rank), "") -> 23 | T24: =IF(is_cat, ADDRESS(sort_min_row, COLUMN(comb_rank)) &":" & ADDRESS(sort_max_row, COLUMN(comb_rank)), "") -> $S$22:$S$36 | U24: =IF(is_cat,RANK(comb_rank,INDIRECT(comb_rank_range),1),"") -> 3 | V24: =IF(is_cat, ADDRESS(sort_min_row, COLUMN(comb_rank_norm)) &":" & ADDRESS(ROW(), COLUMN(comb_rank_norm)), "") -> $U$22:$U$24 | W24: =IF(is_cat, comb_rank_norm + COUNTIF(INDIRECT(comb_rank_norm_run_range), comb_rank_norm)-1, "") -> 4 | X24: =IF(is_cat, header_row_id + comb_rank_unique, row_id) -> 33 | Y24: =IF(is_empty, "", INDEX($J:$J, MATCH(row_id, $X:$X, 0))) -> Groceries | Z24: =IF(is_empty, "", IF(is_header, "Tracked", INDEX($K:$K, MATCH(row_id, $X:$X, 0)))) -> 0 | AA24: =IF(is_empty, "", IF(is_header, "Budget", INDEX($L:$L, MATCH(row_id, $X:$X, 0)))) -> 0 | AB24: =IF(is_empty, "", IF(is_header, "% Compl.", IFERROR(out_tracked / out_budget, "-"))) -> - | AC24: =IF(is_empty, "", IF(is_header, "Remaining", IF(out_budget - out_tracked > 0, out_budget - out_tracked, 0))) -> 0 | AD24: =IF(is_empty, "", IF(is_header, "Excess", IF(out_budget - out_tracked < 0, out_tracked - out_budget, 0))) -> 0
C25: {=IF(C24=-1,-1, IF(C24<income_max_row, C24+1, IF(C24=income_max_row, income_total_row, IF(C24=income_total_row, "/1", IF(C24="/1", expenses_header_row, IF(C24<expenses_max_row, C24+1, IF(C24=expenses_max_row, expenses_total_row, IF(C24=expenses_total_row, "/2", IF(C24="/2", savings_header_row, IF(C24<savings_max_row, C24+1, IF(C24=savings_max_row, savings_total_row, -1)))))))))))} -> 33 | D25: =IF(is_header,row_id, IF(NOT(is_empty),D24,-1)) -> 29 | E25: {=1*OR(row_id=income_header_row, row_id=expenses_header_row, row_id=savings_header_row)} -> 0 | F25: =1*NOT(OR(is_header, is_total, is_empty)) -> 1 | G25: {=1*OR(row_id=income_total_row, row_id=expenses_total_row, row_id=savings_total_row)} -> 0 | H25: =1*OR(row_id="/1", row_id="/2", row_id=-1) -> 0 | I25: {=IFERROR(INDEX('Budget Planning'!$C:$C, header_row_id),"")} -> Expenses | J25: {=IFERROR(INDEX('Budget Planning'!$C:$C, row_id), "")} -> Utilities | K25: {=IF( OR(is_header, is_empty, selected_period=""), "", IF( is_total, IF( selected_period="Total Year", SUMPRODUCT( Tracking[Amount] * (Tracking[Type]=type) * (YEAR(Tracking[Effective Date])=selected_year) ), SUMPRODUCT( Tracking[Amount] * (Tracking[Type]=type) * (YEAR(Tracking[Effective Date])=selected_year) * (MONTH(Tracking[Effective Date])=selected_period) ) ), IF( selected_period="Total Year", SUMPRODUCT( Tracking[Amount] * (Tracking[Type]=type) * (Tracking[Category]=item) * (YEAR(Tracking[Effective Date])=selected_year) ), SUMPRODUCT( Tracking[Amount] * (Tracking[Type]=type) * (Tracking[Category]=item) * (YEAR(Tracking[Effective Date])=selected_year) * (MONTH(Tracking[Effective Date])=selected_period) ) ) ) )} -> 0 | L25: {=IF( OR(is_header, is_empty), "", INDEX( 'Budget Planning'!$E:$FA, row_id, MATCH( IF( selected_period = "Total Year", selected_year, DATE(selected_year, selected_period, 1) ), 'Budget Planning'!$E$10:$FA$10, 0 ) ) )} -> 0 | M25: {=IF( is_cat, IF( header_row_id = income_header_row, MATCH(income_min_row, $C:$C, 0), IF( header_row_id = expenses_header_row, MATCH(expenses_min_row, $C:$C, 0), IF( header_row_id = savings_header_row, MATCH(savings_min_row, $C:$C, 0), "" ) ) ), "" )} -> 22 | N25: {=IF( is_cat, IF( header_row_id = income_header_row, MATCH(income_max_row, $C:$C, 0), IF( header_row_id = expenses_header_row, MATCH(expenses_max_row, $C:$C, 0), IF( header_row_id = savings_header_row, MATCH(savings_max_row, $C:$C, 0), "" ) ) ), "" )} -> 36 | O25: =IF(is_cat, ADDRESS(sort_min_row, COLUMN(tracked)) &":" & ADDRESS(sort_max_row, COLUMN(tracked)), "") -> $K$22:$K$36 | P25: =IF(is_cat, RANK(tracked, INDIRECT(tracked_range), 0), "") -> 2 | Q25: =IF(is_cat, ADDRESS(sort_min_row, COLUMN(budget)) &":" & ADDRESS(sort_max_row, COLUMN(budget)), "") -> $L$22:$L$36 | R25: =IF(is_cat, RANK(budget, INDIRECT(budget_range), 0), "") -> 3 | S25: =IF(is_cat, _xlfn.NUMBERVALUE(tracked_rank & budget_rank), "") -> 23 | T25: =IF(is_cat, ADDRESS(sort_min_row, COLUMN(comb_rank)) &":" & ADDRESS(sort_max_row, COLUMN(comb_rank)), "") -> $S$22:$S$36 | U25: =IF(is_cat,RANK(comb_rank,INDIRECT(comb_rank_range),1),"") -> 3 | V25: =IF(is_cat, ADDRESS(sort_min_row, COLUMN(comb_rank_norm)) &":" & ADDRESS(ROW(), COLUMN(comb_rank_norm)), "") -> $U$22:$U$25 | W25: =IF(is_cat, comb_rank_norm + COUNTIF(INDIRECT(comb_rank_norm_run_range), comb_rank_norm)-1, "") -> 5 | X25: =IF(is_cat, header_row_id + comb_rank_unique, row_id) -> 34 | Y25: =IF(is_empty, "", INDEX($J:$J, MATCH(row_id, $X:$X, 0))) -> Transport | Z25: =IF(is_empty, "", IF(is_header, "Tracked", INDEX($K:$K, MATCH(row_id, $X:$X, 0)))) -> 0 | AA25: =IF(is_empty, "", IF(is_header, "Budget", INDEX($L:$L, MATCH(row_id, $X:$X, 0)))) -> 0 | AB25: =IF(is_empty, "", IF(is_header, "% Compl.", IFERROR(out_tracked / out_budget, "-"))) -> - | AC25: =IF(is_empty, "", IF(is_header, "Remaining", IF(out_budget - out_tracked > 0, out_budget - out_tracked, 0))) -> 0 | AD25: =IF(is_empty, "", IF(is_header, "Excess", IF(out_budget - out_tracked < 0, out_tracked - out_budget, 0))) -> 0
C26: {=IF(C25=-1,-1, IF(C25<income_max_row, C25+1, IF(C25=income_max_row, income_total_row, IF(C25=income_total_row, "/1", IF(C25="/1", expenses_header_row, IF(C25<expenses_max_row, C25+1, IF(C25=expenses_max_row, expenses_total_row, IF(C25=expenses_total_row, "/2", IF(C25="/2", savings_header_row, IF(C25<savings_max_row, C25+1, IF(C25=savings_max_row, savings_total_row, -1)))))))))))} -> 34 | D26: =IF(is_header,row_id, IF(NOT(is_empty),D25,-1)) -> 29 | E26: {=1*OR(row_id=income_header_row, row_id=expenses_header_row, row_id=savings_header_row)} -> 0 | F26: =1*NOT(OR(is_header, is_total, is_empty)) -> 1 | G26: {=1*OR(row_id=income_total_row, row_id=expenses_total_row, row_id=savings_total_row)} -> 0 | H26: =1*OR(row_id="/1", row_id="/2", row_id=-1) -> 0 | I26: {=IFERROR(INDEX('Budget Planning'!$C:$C, header_row_id),"")} -> Expenses | J26: {=IFERROR(INDEX('Budget Planning'!$C:$C, row_id), "")} -> Insurance | K26: {=IF( OR(is_header, is_empty, selected_period=""), "", IF( is_total, IF( selected_period="Total Year", SUMPRODUCT( Tracking[Amount] * (Tracking[Type]=type) * (YEAR(Tracking[Effective Date])=selected_year) ), SUMPRODUCT( Tracking[Amount] * (Tracking[Type]=type) * (YEAR(Tracking[Effective Date])=selected_year) * (MONTH(Tracking[Effective Date])=selected_period) ) ), IF( selected_period="Total Year", SUMPRODUCT( Tracking[Amount] * (Tracking[Type]=type) * (Tracking[Category]=item) * (YEAR(Tracking[Effective Date])=selected_year) ), SUMPRODUCT( Tracking[Amount] * (Tracking[Type]=type) * (Tracking[Category]=item) * (YEAR(Tracking[Effective Date])=selected_year) * (MONTH(Tracking[Effective Date])=selected_period) ) ) ) )} -> 0 | L26: {=IF( OR(is_header, is_empty), "", INDEX( 'Budget Planning'!$E:$FA, row_id, MATCH( IF( selected_period = "Total Year", selected_year, DATE(selected_year, selected_period, 1) ), 'Budget Planning'!$E$10:$FA$10, 0 ) ) )} -> 0 | M26: {=IF( is_cat, IF( header_row_id = income_header_row, MATCH(income_min_row, $C:$C, 0), IF( header_row_id = expenses_header_row, MATCH(expenses_min_row, $C:$C, 0), IF( header_row_id = savings_header_row, MATCH(savings_min_row, $C:$C, 0), "" ) ) ), "" )} -> 22 | N26: {=IF( is_cat, IF( header_row_id = income_header_row, MATCH(income_max_row, $C:$C, 0), IF( header_row_id = expenses_header_row, MATCH(expenses_max_row, $C:$C, 0), IF( header_row_id = savings_header_row, MATCH(savings_max_row, $C:$C, 0), "" ) ) ), "" )} -> 36 | O26: =IF(is_cat, ADDRESS(sort_min_row, COLUMN(tracked)) &":" & ADDRESS(sort_max_row, COLUMN(tracked)), "") -> $K$22:$K$36 | P26: =IF(is_cat, RANK(tracked, INDIRECT(tracked_range), 0), "") -> 2 | Q26: =IF(is_cat, ADDRESS(sort_min_row, COLUMN(budget)) &":" & ADDRESS(sort_max_row, COLUMN(budget)), "") -> $L$22:$L$36 | R26: =IF(is_cat, RANK(budget, INDIRECT(budget_range), 0), "") -> 3 | S26: =IF(is_cat, _xlfn.NUMBERVALUE(tracked_rank & budget_rank), "") -> 23 | T26: =IF(is_cat, ADDRESS(sort_min_row, COLUMN(comb_rank)) &":" & ADDRESS(sort_max_row, COLUMN(comb_rank)), "") -> $S$22:$S$36 | U26: =IF(is_cat,RANK(comb_rank,INDIRECT(comb_rank_range),1),"") -> 3 | V26: =IF(is_cat, ADDRESS(sort_min_row, COLUMN(comb_rank_norm)) &":" & ADDRESS(ROW(), COLUMN(comb_rank_norm)), "") -> $U$22:$U$26 | W26: =IF(is_cat, comb_rank_norm + COUNTIF(INDIRECT(comb_rank_norm_run_range), comb_rank_norm)-1, "") -> 6 | X26: =IF(is_cat, header_row_id + comb_rank_unique, row_id) -> 35 | Y26: =IF(is_empty, "", INDEX($J:$J, MATCH(row_id, $X:$X, 0))) -> Utilities | Z26: =IF(is_empty, "", IF(is_header, "Tracked", INDEX($K:$K, MATCH(row_id, $X:$X, 0)))) -> 0 | AA26: =IF(is_empty, "", IF(is_header, "Budget", INDEX($L:$L, MATCH(row_id, $X:$X, 0)))) -> 0 | AB26: =IF(is_empty, "", IF(is_header, "% Compl.", IFERROR(out_tracked / out_budget, "-"))) -> - | AC26: =IF(is_empty, "", IF(is_header, "Remaining", IF(out_budget - out_tracked > 0, out_budget - out_tracked, 0))) -> 0 | AD26: =IF(is_empty, "", IF(is_header, "Excess", IF(out_budget - out_tracked < 0, out_tracked - out_budget, 0))) -> 0
